Workbook

Sheet overview
A1: overview
C2: aa | D2: nf | E2: nm | F2: mf | G2: mm | H2: na | I2: ma | J2: af | K2: am
B3: {=C11&" / "&C12} -> FR / France | C3: All | D3: Native Female | E3: Native Male | F3: Migrant Female | G3: Migrant Male | H3: Utility Native Male + Female | I3: Utility Migrant Male + Female | J3: Utility All Female | K3: Utility All Male | L3: Utility Other
B4: Information | C4: This column contains general values (like definitions and sources) | D4: This column is important for the correct calculation | E4: This column is important for the correct calculation | F4: This column is important for the correct calculation | G4: This column is important for the correct calculation | H4: This column only contains utilty values used to calculate the data on the left | I4: This column only contains utilty values used to calculate the data on the left | J4: This column only contains utilty values used to calculate the data on the left | K4: This column only contains utilty values used to calculate the data on the left | L4: This column only contains utilty values used to calculate the data on the left
B5: Editing this spreadsheet | C5: On a blue background, you can edit values and formulas
C6: On a green background, only change the formula (normally the formula should be right though)
C7: On a yellow background, don't change anything!
C8: On a dark grey background, you find important instructions
B10: Country
A11: na | B11: Acronym (e.g. "DE") | C11: FR
A12: nn | B12: Name | C12: France
A13: nd | B13: Date when the sheets were generated | C13: 2026-05-22 14:00
B15: Estimation | C15: This is an estimation of the tipping point
B17: Current population | C17: {=H17+I17} -> 68882600 | D17: {=C34} -> 0.21791555 | E17: pn, pm | H17: {=population!H109} -> 53872010 | I17: {=population!I109} -> 15010590
B18: Gap native - migrant | C18: {=H17-I17} -> 38861420 | D18: {=C18/C17} -> 0.56416889
B19: Birth / year according to population | H19: {=population!H9} -> 459933 | I19: {=population!I9} -> 153997
B20: Birth / year according to fertility | H20: {=births!H11} -> 424062.65 | I20: {=births!I11} -> 189867.35
B21: Birth / year used for estimation | D21: We prefer the number of births according to the fertility | H21: {=IF(ISNUMBER(H20),H20,H19)} -> 424062.65 | I21: {=IF(ISNUMBER(I20),I20,I19)} -> 189867.35
B22: Deaths / year | H22: {=-deaths!H107} -> -532756 | I22: {=-deaths!I107} -> -110576
B23: Migration balance / year | H23: {=migration!H9} -> -70499.7 | I23: {=migration!I9} -> 196534.9
B24: Population delta / year | C24: {=I24-H24} -> 455019.31 | D24: {=C24/C17} -> 0.006605722 | E24: dn, dm | H24: {=H21+H22+H23} -> -179193.05 | I24: {=I21+I22+I23} -> 275826.25
B26: Years until 33% share of migrants | C26: {=(H$17-2*I$17)/(2*I$24-H$24)} -> 32.634569 | D26: y = (pn - 2*pm) / (2*dm - dn)
B27: Estimated tipping point for 33% share of migrants | C27: {=C$33+C26} -> 2057.6346
B28: Years until 50% share of migrants | C28: {=(H$17-I$17)/(I$24-H$24)} -> 85.40609 | D28: y = (pn - pm) / (dm - dn)
B29: Estimated tipping point for 50% share of migrants | C29: {=C$33+C28} -> 2110.4061
B31: Indicators | C31: This indicators are used to find differences between countries and thus show where the data collection might be wrong
B33: Year of the population numbers | C33: {=population!C7} -> 2025
B34: Share of migrant population | C34: {=population!I109/population!C109} -> 0.21791555 | D34: > 20% normally
B35: Births per 1 mio. women (15-49) | C35: {=I35/H35-1} -> 0.35294118 | D35: > 30% normally | H35: {=births!H11/births!D9*1000000} -> 38641.758 | I35: {=births!I11/births!F9*1000000} -> 52280.025
B36: Births per 1 mio. population | C36: {=I36/H36-1} -> 0.60688832 | D36: > 50% normally due to younger migrant population | H36: {=births!H11/population!H109*1000000} -> 7871.6693 | I36: {=births!I11/population!I109*1000000} -> 12648.893
B37: Deaths per 1 mio. population | C37: {=I37/H37-1} -> -0.25510005 | D37: < 0% normally due to younger migrant population | H37: {=deaths!H$107/population!H$109*1000000} -> 9889.2913 | I37: {=deaths!I$107/population!I$109*1000000} -> 7366.5326
B38: Migration balance per 1 mio. of group | H38: {=migration!H111/population!H109*1000000} -> -1308.6517 | I38: {=migration!I111/population!I109*1000000} -> 13093.083
B39: Migration balance in % of population | H39: {=migration!H111/population!C109} -> -0.0010234762 | I39: {=migration!I111/population!D109} -> 0.0070583898
B47: Migration Background | C47: How is the "Migration Background" defined in this country?
A49: i | B49: Definition of the 'migration background' | C49: MH i.w.S. nach INSEE-Definition: immigré (personne née étrangère à l'étranger et résidant en France; bleibt immigré auch nach Erwerb der frz. StAng) + descendant d'immigrés (en France geboren, mit mindestens einem immigré-Elternteil). 3. Generation nicht modelliert (V2-Thema TeO2).
A51: is | B51: Source of the data (verbal) | C51: {=IF(C52="","?",C52)&IF(C53="","","; downloaded "&C53)&IF(C54="","","; "&C54)} -> https://www.insee.fr/fr/metadonnees/definition/c1676; downloaded 2026-05-22
B52: URLs, where the data was found | C52: https://www.insee.fr/fr/metadonnees/definition/c1676
B53: Date, when the data was downloaded | C53: 2026-05-22
B54: Manual remarks (not for AI!)
B55: Remarks of the AI (e.g. calculation) | C55: Variante B (INSEE-strikt): MH-Total = Immigrés + Descendants. Eingebürgerte Migranten bleiben immigré (INSEE-Definition). Français nés à l'étranger sind NICHT immigré → werden als Native gezählt (Diff zu Eurostat-FB-Konzept ca. 2,6 Mio.). PROJECT.md-Vorgabe: Variante B methodisch korrekt.
...

Sheet population
A1: population
C2: aa | D2: nf | E2: nm | F2: mf | G2: mm | H2: na | I2: ma | J2: af | K2: am
B3: {=overview!C11&" / "&overview!C12} -> FR / France | C3: All | D3: Native Female | E3: Native Male | F3: Migrant Female | G3: Migrant Male | H3: Utility Native Male + Female | I3: Utility Migrant Male + Female | J3: Utility All Female | K3: Utility All Male | L3: Utility Other
B4: ⚠️ | C4: Do not add or delete lines until the next dark grey row below! The fields below are the fields used in other sheets and in the calculation. The address of these fields and their contents must remain always the same, so we can add calculations later!
B5: Population | C5: This is the base line of the caclution
A7: py | B7: Year of the count of the population | C7: 2025
A9: p00 | B9: 0 years | C9: {=H9+I9} -> 613930 | D9: {=D121} -> 223160 | E9: {=E121} -> 236773 | F9: {=F121} -> 76749 | G9: {=G121} -> 77248 | H9: {=E9+D9} -> 459933 | I9: {=G9+F9} -> 153997 | J9: {=D9+F9} -> 299909 | K9: {=E9+G9} -> 314021
A10: p01 | B10: 1 years | C10: {=H10+I10} -> 633124 | D10: {=D122} -> 230533 | E10: {=E122} -> 243780 | F10: {=F122} -> 79161 | G10: {=G122} -> 79650 | H10: {=E10+D10} -> 474313 | I10: {=G10+F10} -> 158811 | J10: {=D10+F10} -> 309694 | K10: {=E10+G10} -> 323430
A11: p02 | B11: 2 years | C11: {=H11+I11} -> 680945 | D11: {=D123} -> 247647 | E11: {=E123} -> 262491 | F11: {=F123} -> 85131 | G11: {=G123} -> 85676 | H11: {=E11+D11} -> 510138 | I11: {=G11+F11} -> 170807 | J11: {=D11+F11} -> 332778 | K11: {=E11+G11} -> 348167
A12: p03 | B12: 3 years | C12: {=H12+I12} -> 707427 | D12: {=D124} -> 258010 | E12: {=E124} -> 271968 | F12: {=F124} -> 88466 | G12: {=G124} -> 88983 | H12: {=E12+D12} -> 529978 | I12: {=G12+F12} -> 177449 | J12: {=D12+F12} -> 346476 | K12: {=E12+G12} -> 360951
A13: p04 | B13: 4 years | C13: {=H13+I13} -> 711837 | D13: {=D125} -> 259140 | E13: {=E125} -> 274142 | F13: {=F125} -> 89001 | G13: {=G125} -> 89554 | H13: {=E13+D13} -> 533282 | I13: {=G13+F13} -> 178555 | J13: {=D13+F13} -> 348141 | K13: {=E13+G13} -> 363696
A14: p05 | B14: 5 years | C14: {=H14+I14} -> 738384 | D14: {=D126} -> 267392 | E14: {=E126} -> 285777 | F14: {=F126} -> 92274 | G14: {=G126} -> 92941 | H14: {=E14+D14} -> 553169 | I14: {=G14+F14} -> 185215 | J14: {=D14+F14} -> 359666 | K14: {=E14+G14} -> 378718
A15: p06 | B15: 6 years | C15: {=H15+I15} -> 747315 | D15: {=D127} -> 271396 | E15: {=E127} -> 288465 | F15: {=F127} -> 93415 | G15: {=G127} -> 94039 | H15: {=E15+D15} -> 559861 | I15: {=G15+F15} -> 187454 | J15: {=D15+F15} -> 364811 | K15: {=E15+G15} -> 382504
A16: p07 | B16: 7 years | C16: {=H16+I16} -> 762141 | D16: {=D128} -> 274735 | E16: {=E128} -> 296232 | F16: {=F128} -> 95201 | G16: {=G128} -> 95973 | H16: {=E16+D16} -> 570967 | I16: {=G16+F16} -> 191174 | J16: {=D16+F16} -> 369936 | K16: {=E16+G16} -> 392205
A17: p08 | B17: 8 years | C17: {=H17+I17} -> 783490 | D17: {=D129} -> 283507 | E17: {=E129} -> 303454 | F17: {=F129} -> 97903 | G17: {=G129} -> 98626 | H17: {=E17+D17} -> 586961 | I17: {=G17+F17} -> 196529 | J17: {=D17+F17} -> 381410 | K17: {=E17+G17} -> 402080
A18: p09 | B18: 9 years | C18: {=H18+I18} -> 805772 | D18: {=D130} -> 292809 | E18: {=E130} -> 310845 | F18: {=F130} -> 100729 | G18: {=G130} -> 101389 | H18: {=E18+D18} -> 603654 | I18: {=G18+F18} -> 202118 | J18: {=D18+F18} -> 393538 | K18: {=E18+G18} -> 412234
A19: p10 | B19: 10 years | C19: {=H19+I19} -> 828311 | D19: {=D131} -> 301901 | E19: {=E131} -> 318639 | F19: {=F131} -> 103576 | G19: {=G131} -> 104195 | H19: {=E19+D19} -> 620540 | I19: {=G19+F19} -> 207771 | J19: {=D19+F19} -> 405477 | K19: {=E19+G19} -> 422834
A20: p11 | B20: 11 years | C20: {=H20+I20} -> 834912 | D20: {=D132} -> 303966 | E20: {=E132} -> 321519 | F20: {=F132} -> 104390 | G20: {=G132} -> 105037 | H20: {=E20+D20} -> 625485 | I20: {=G20+F20} -> 209427 | J20: {=D20+F20} -> 408356 | K20: {=E20+G20} -> 426556
... A108: p99 | B108: 99 years and older | C108: {=H108+I108} -> 55321 | D108: {=D220} -> 40488 | E108: {=E220} -> 5987 | F108: {=F220} -> 6117 | G108: {=G220} -> 2729 | H108: {=E108+D108} -> 46475 | I108: {=G108+F108} -> 8846 | J108: {=D108+F108} -> 46605 | K108: {=E108+G108} -> 8716
A109: pt | B109: Total | C109: {=SUM(C9:C108)} -> 68882600 | D109: {=SUM(D9:D108)} -> 27844155 | E109: {=SUM(E9:E108)} -> 26027855 | F109: {=SUM(F9:F108)} -> 7604375 | G109: {=SUM(G9:G108)} -> 7406215 | H109: {=SUM(H9:H108)} -> 53872010 | I109: {=SUM(I9:I108)} -> 15010590 | J109: {=D109+F109} -> 35448530 | K109: {=E109+G109} -> 33434070
A111: ps | B111: Source of the data (verbal) | C111: {=IF(C112="","?",C112)&IF(C113="","","; downloaded "&C113)&IF(C114="","","; "&C114)} -> https://ec.europa.eu/eurostat/databrowser/view/demo_pjan, https://www.insee.fr/fr/statistiques/8582067, https://www.insee.fr/fr/statistiques/4187125; downloaded 2026-05-22
B112: URLs, where the data was found | C112: https://ec.europa.eu/eurostat/databrowser/view/demo_pjan, https://www.insee.fr/fr/statistiques/8582067, https://www.insee.fr/fr/statistiques/4187125
B113: Date, when the data was downloaded | C113: 2026-05-22
B114: Manual remarks (not for AI!)
B115: Remarks of the AI (e.g. calculation) | C115: Pop-Total per Einzelalter × Sex aus Eurostat demo_pjan 2025 (geo=FR, France entière, Total 68,882,600). 1. Generation Migrant (immigré) aus INSEE RP2022 IMG1B (4 broad bins × Sex × 11 Origine-Regionen, France entière, Géographie 01/01/2025) Total = 7.023.595; disaggregiert auf Einzelalter über Pop-Total-Form innerhalb jedes Bandes (analog AT-Mikrozensus-Disaggregation, CLAUDE.md). 2. Generation (descendants d'immigrés) aus INSEE Insee Références 2024 (Décembre 2024, enquête Emploi 2024, France hors Mayotte, logement ordinaire) Total = 7.987.000 in 4 Banden (31,3%/18%/31,2%/19,5%); disaggregiert auf Einzelalter über Pop-Total-Form. Sex-Split der Descendants nicht öffentlich publiziert → 50/50-Konvention (Plan-Entscheidung; Alternative leer würde INSEE-Definition zerstören). Migrant = 1.Gen + 2.Gen = 15,010,590 (21.8%). Native = Pop − Migrant. Approximationen: (a) 1.-Gen-Quote innerhalb 4-Bin konstant; (b) Descendants-Sex-Split 50/50; (c) Geographic-Mismatch Eurostat (France entière inkl. Mayotte) vs. INSEE-Descendants (hors Mayotte) — Diff <30 K. Variante A (Eurostat-FB direkt, ohne INSEE-Strikt-Filter) wäre breiter (~25 % Migrant), aber methodisch-falsch für FR (PROJECT.md). 3. Generation nicht modelliert (V2-Thema TeO2).
B116: Internal remarks
B118: ✏️ | C118: Enter your data below and make sure that you adjust the formulas above, if necessary. If calculations are necessary, use the fields below for it and use formulas in the area above, to fill in the fields above exactly as intended.
B119: Population | C119: Calculation of the population
B121: 0 years | D121: 223160 | E121: 236773 | F121: 76749 | G121: 77248
B122: 1 years | D122: 230533 | E122: 243780 | F122: 79161 | G122: 79650
B123: 2 years | D123: 247647 | E123: 262491 | F123: 85131 | G123: 85676
B124: 3 years | D124: 258010 | E124: 271968 | F124: 88466 | G124: 88983
B125: 4 years | D125: 259140 | E125: 274142 | F125: 89001 | G125: 89554
B126: 5 years | D126: 267392 | E126: 285777 | F126: 92274 | G126: 92941
B127: 6 years | D127: 271396 | E127: 288465 | F127: 93415 | G127: 94039
B128: 7 years | D128: 274735 | E128: 296232 | F128: 95201 | G128: 95973
B129: 8 years | D129: 283507 | E129: 303454 | F129: 97903 | G129: 98626
B130: 9 years | D130: 292809 | E130: 310845 | F130: 100729 | G130: 101389
B131: 10 years | D131: 301901 | E131: 318639 | F131: 103576 | G131: 104195
B132: 11 years | D132: 303966 | E132: 321519 | F132: 104390 | G132: 105037
...

Sheet births
A1: births
C2: aa | D2: nf | E2: nm | F2: mf | G2: mm | H2: na | I2: ma | J2: af | K2: am
B3: {=overview!C11&" / "&overview!C12} -> FR / France | C3: All | D3: Native Female | E3: Native Male | F3: Migrant Female | G3: Migrant Male | H3: Utility Native Male + Female | I3: Utility Migrant Male + Female | J3: Utility All Female | K3: Utility All Male | L3: Utility Other
B4: ⚠️ | C4: Do not add or delete lines until the next dark grey row below! The fields below are the fields used in other sheets and in the calculation. The address of these fields and their contents must remain always the same, so we can add calculations later!
B5: Fertility | C5: The values in this section are used to calculate the number of births in the population goups
A7: f | B7: Official fertility rate | C7: 2024 | D7: 1.7 | F7: 2.3
B8: Population of age 0 (=births) | C8: {=population!C9} -> 613930 | D8: {=population!D9} -> 223160 | E8: {=population!E9} -> 236773 | F8: {=population!F9} -> 76749 | G8: {=population!G9} -> 77248 | H8: {=population!H9} -> 459933 | I8: {=population!I9} -> 153997 | J8: {=population!J9} -> 299909 | K8: {=population!K9} -> 314021
B9: Population of women of age 15-49 | D9: {=SUM(population!D24:D58)} -> 10974207 | F9: {=SUM(population!F24:F58)} -> 3631738
B10: Factor: fertile women x fertility rate | C10: {=D10+F10} -> 27009149 | D10: {=D9*D7} -> 18656152 | F10: {=F9*F7} -> 8352997.4
A11: f00 | B11: Calculated births by fertility rate | C11: {=H11+I11} -> 613930 | D11: {=(D8+F8)*D10/C10} -> 207157.5 | E11: {=(E8+G8)*D10/C10} -> 216905.15 | F11: {=(D8+F8)*F10/C10} -> 92751.499 | G11: {=(E8+G8)*F10/C10} -> 97115.854 | H11: {=E11+D11} -> 424062.65 | I11: {=G11+F11} -> 189867.35 | J11: {=D11+F11} -> 299909 | K11: {=E11+G11} -> 314021
A13: fs | B13: Source of the data (verbal) | C13: {=IF(C14="","?",C14)&IF(C15="","","; downloaded "&C15)&IF(C16="","","; "&C16)} -> https://www.insee.fr/fr/statistiques/6801884, https://www.insee.fr/fr/statistiques/6793238; downloaded 2026-05-22
B14: URLs, where the data was found | C14: https://www.insee.fr/fr/statistiques/6801884, https://www.insee.fr/fr/statistiques/6793238
B15: Date, when the data was downloaded | C15: 2026-05-22
B16: Manual remarks (not for AI!)
B17: Remarks of the AI (e.g. calculation) | C17: TFR nach lieu de naissance Mutter (INSEE Insee Première 1939, Februar 2023, jüngste publizierte Werte mit immigré-Aufschlüsselung): TFR Native (femmes nées en France) = 1,70; TFR Migrant (femmes immigrées) = 2,30 für 2021. INSEE Bilan démographique 2025 (jüngste Publikation) hat KEINE lieu-de-naissance-Aufschlüsselung; nur Total-ICF (1,56 für 2025; 1,62 für 2024). Methodische Approximation (CLAUDE.md §Fertilität): TFR-immigré wird auf gesamte Migrant-Pop angewendet inkl. Descendants — diese haben faktisch TFR näher an Native, was zu leichter Überschätzung Migrant-Geburten führt. Bewusste Approximation lt. CLAUDE.md, keine Korrektur.
B18: Internal remarks
B20: Births | C20: The values in this section are used to calculate at which age of the mother the children are born
A22: b15 | B22: 15 years and younger age of the mother | C22: {=D22+E22+F22+G22} -> 362.33305 | D22: {=D$11*$H22/$H$57} -> 92.394558 | E22: {=E$11*$H22/$H$57} -> 96.742117 | F22: {=F$11*$I22/$I$57} -> 84.607613 | G22: {=G$11*$I22/$I$57} -> 88.588762 | H22: {=H74} -> 218 | I22: {=I74} -> 157 | J22: {=D22+F22} -> 177.00217 | K22: {=E22+G22} -> 185.33088
A23: b16 | B23: 16 years age of the mother | C23: {=D23+E23+F23+G23} -> 890.84872 | D23: {=D$11*$H23/$H$57} -> 264.89266 | E23: {=E$11*$H23/$H$57} -> 277.35699 | F23: {=F$11*$I23/$I$57} -> 170.29303 | G23: {=G$11*$I23/$I$57} -> 178.30604 | H23: {=H75} -> 625 | I23: {=I75} -> 316 | J23: {=D23+F23} -> 435.18569 | K23: {=E23+G23} -> 455.66303
A24: b17 | B24: 17 years age of the mother | C24: {=D24+E24+F24+G24} -> 1557.399 | D24: {=D$11*$H24/$H$57} -> 508.5939 | E24: {=E$11*$H24/$H$57} -> 532.52542 | F24: {=F$11*$I24/$I$57} -> 252.20613 | G24: {=G$11*$I24/$I$57} -> 264.07351 | H24: {=H76} -> 1200 | I24: {=I76} -> 468 | J24: {=D24+F24} -> 760.80003 | K24: {=E24+G24} -> 796.59892
A25: b18 | B25: 18 years age of the mother | C25: {=D25+E25+F25+G25} -> 2836.6336 | D25: {=D$11*$H25/$H$57} -> 971.83818 | E25: {=E$11*$H25/$H$57} -> 1017.5673 | F25: {=F$11*$I25/$I$57} -> 413.87673 | G25: {=G$11*$I25/$I$57} -> 433.3514 | H25: {=H77} -> 2293 | I25: {=I77} -> 768 | J25: {=D25+F25} -> 1385.7149 | K25: {=E25+G25} -> 1450.9187
A26: b19 | B26: 19 years age of the mother | C26: {=D26+E26+F26+G26} -> 5200.0258 | D26: {=D$11*$H26/$H$57} -> 1830.5142 | E26: {=E$11*$H26/$H$57} -> 1916.6477 | F26: {=F$11*$I26/$I$57} -> 709.73392 | G26: {=G$11*$I26/$I$57} -> 743.12994 | H26: {=H78} -> 4319 | I26: {=I78} -> 1317 | J26: {=D26+F26} -> 2540.2481 | K26: {=E26+G26} -> 2659.7777
A27: b20 | B27: 20 years age of the mother | C27: {=D27+E27+F27+G27} -> 7672.0205 | D27: {=D$11*$H27/$H$57} -> 2618.8348 | E27: {=E$11*$H27/$H$57} -> 2742.0621 | F27: {=F$11*$I27/$I$57} -> 1128.9997 | G27: {=G$11*$I27/$I$57} -> 1182.1239 | H27: {=H79} -> 6179 | I27: {=I79} -> 2095 | J27: {=D27+F27} -> 3747.8344 | K27: {=E27+G27} -> 3924.1861
A28: b21 | B28: 21 years age of the mother | C28: {=D28+E28+F28+G28} -> 10299.551 | D28: {=D$11*$H28/$H$57} -> 3482.5967 | E28: {=E$11*$H28/$H$57} -> 3646.4678 | F28: {=F$11*$I28/$I$57} -> 1548.8043 | G28: {=G$11*$I28/$I$57} -> 1621.6822 | H28: {=H80} -> 8217 | I28: {=I80} -> 2874 | J28: {=D28+F28} -> 5031.4011 | K28: {=E28+G28} -> 5268.15
A29: b22 | B29: 22 years age of the mother | C29: {=D29+E29+F29+G29} -> 12999.474 | D29: {=D$11*$H29/$H$57} -> 4495.9701 | E29: {=E$11*$H29/$H$57} -> 4707.5247 | F29: {=F$11*$I29/$I$57} -> 1854.3618 | G29: {=G$11*$I29/$I$57} -> 1941.6174 | H29: {=H81} -> 10608 | I29: {=I81} -> 3441 | J29: {=D29+F29} -> 6350.3318 | K29: {=E29+G29} -> 6649.1421
A30: b23 | B30: 23 years age of the mother | C30: {=D30+E30+F30+G30} -> 17040.549 | D30: {=D$11*$H30/$H$57} -> 5843.3201 | E30: {=E$11*$H30/$H$57} -> 6118.2733 | F30: {=F$11*$I30/$I$57} -> 2481.1048 | G30: {=G$11*$I30/$I$57} -> 2597.8513 | H30: {=H82} -> 13787 | I30: {=I82} -> 4604 | J30: {=D30+F30} -> 8324.4248 | K30: {=E30+G30} -> 8716.1246
A31: b24 | B31: 24 years age of the mother | C31: {=D31+E31+F31+G31} -> 21059.359 | D31: {=D$11*$H31/$H$57} -> 7127.5197 | E31: {=E$11*$H31/$H$57} -> 7462.8999 | F31: {=F$11*$I31/$I$57} -> 3160.1213 | G31: {=G$11*$I31/$I$57} -> 3308.8185 | H31: {=H83} -> 16817 | I31: {=I83} -> 5864 | J31: {=D31+F31} -> 10287.641 | K31: {=E31+G31} -> 10771.718
A32: b25 | B32: 25 years age of the mother | C32: {=D32+E32+F32+G32} -> 24615.802 | D32: {=D$11*$H32/$H$57} -> 8459.6119 | E32: {=E$11*$H32/$H$57} -> 8857.6728 | F32: {=F$11*$I32/$I$57} -> 3565.3756 | G32: {=G$11*$I32/$I$57} -> 3733.1417 | H32: {=H84} -> 19960 | I32: {=I84} -> 6616 | J32: {=D32+F32} -> 12024.987 | K32: {=E32+G32} -> 12590.814
A33: b26 | B33: 26 years age of the mother | C33: {=D33+E33+F33+G33} -> 29103.139 | D33: {=D$11*$H33/$H$57} -> 9984.5459 | E33: {=E$11*$H33/$H$57} -> 10454.361 | F33: {=F$11*$I33/$I$57} -> 4232.5362 | G33: {=G$11*$I33/$I$57} -> 4431.6952 | H33: {=H85} -> 23558 | I33: {=I85} -> 7854 | J33: {=D33+F33} -> 14217.082 | K33: {=E33+G33} -> 14886.057
... A56: b49 | B56: 49 years and older age of the mother | C56: {=D56+E56+F56+G56} -> 129.83467 | D56: {=D$11*$H56/$H$57} -> 28.396493 | E56: {=E$11*$H56/$H$57} -> 29.732669 | F56: {=F$11*$I56/$I$57} -> 35.028629 | G56: {=G$11*$I56/$I$57} -> 36.676876 | H56: {=H108} -> 67 | I56: {=I108} -> 65 | J56: {=D56+F56} -> 63.425122 | K56: {=E56+G56} -> 66.409545
A57: bt | B57: Total | C57: {=SUM(C22:C56)} -> 613930 | D57: {=SUM(D22:D56)} -> 207157.5 | E57: {=SUM(E22:E56)} -> 216905.15 | F57: {=SUM(F22:F56)} -> 92751.499 | G57: {=SUM(G22:G56)} -> 97115.854 | H57: {=SUM(H22:H56)} -> 488777 | I57: {=SUM(I22:I56)} -> 172112 | J57: {=SUM(J22:J56)} -> 299909 | K57: {=SUM(K22:K56)} -> 314021
A59: bs | B59: Source of the data (verbal) | C59: {=IF(C60="","?",C60)&IF(C61="","","; downloaded "&C61)&IF(C62="","","; "&C62)} -> siehe C14 (TFR-Quelle); ASFR-Shape aus Eurostat demo_facbc 2024; downloaded 2026-05-22
B60: URLs, where the data was found | C60: siehe C14 (TFR-Quelle); ASFR-Shape aus Eurostat demo_facbc 2024
B61: Date, when the data was downloaded | C61: 2026-05-22
B62: Manual remarks (not for AI!)
B63: Remarks of the AI (e.g. calculation) | C63: ASFR-Shape per Mutter-Alter in H74:H108 (Native, c_birth=NAT) und I74:I108 (Migrant, c_birth=FOR) aus Eurostat demo_facbc 2024 (geo=FR; Geburten × Einzelalter Y15-Y49 × c_birth). Eurostat publiziert Single-Year-Ages für FR — direkt übernommen, kein Bin-Disaggregation nötig. Vorlagen-Formel Z. 22-56: D22 = D$11×$H22/$H$57 — H22 = H74 (Pull) → ASFR-Shape normiert sich intern via H22/H57. Die absolute Native-Geburten-Anzahl (H11 = 424.063 für 2024) wird über Top-Block-Formel berechnet: Total-Pop-Age-0 × Native-Birth-Factor-Ratio (D10/C10). Modell-Approximation (CLAUDE.md §Fertilität): TFR-immigré wird auf gesamte Migrant-Pop angewandt inkl. Descendants, die faktisch TFR näher an Native haben — bewusst, keine Korrektur.
B64: Internal remarks
B66: ✏️ | C66: Enter your data below and make sure that you adjust the formulas above, if necessary. If calculations are necessary, use the fields below for it and use formulas in the area above, to fill in the fields above exactly as intended.
B67: Births | C67: Calculation of the births
B68: Use the fields of this row, if numbers for age, natives/migrants are known
...

Sheet deaths
A1: deaths
C2: aa | D2: nf | E2: nm | F2: mf | G2: mm | H2: na | I2: ma | J2: af | K2: am
B3: {=overview!C11&" / "&overview!C12} -> FR / France | C3: All | D3: Native Female | E3: Native Male | F3: Migrant Female | G3: Migrant Male | H3: Utility Native Male + Female | I3: Utility Migrant Male + Female | J3: Utility All Female | K3: Utility All Male | L3: Utility Other
B4: ⚠️ | C4: Do not add or delete lines until the next dark grey row below! The fields below are the fields used in other sheets and in the calculation. The address of these fields and their contents must remain always the same, so we can add calculations later!
B5: Deaths | C5: This table is needed to calculate the Leslie matrix
A7: d00 | B7: 0 years age of the deceased | C7: 2024 | D7: {=D119} -> 891 | E7: {=E119} -> 1141 | F7: {=F119} -> 306 | G7: {=G119} -> 372 | H7: {=E7+D7} -> 2032 | I7: {=G7+F7} -> 678 | J7: {=D7+F7} -> 1197 | K7: {=E7+G7} -> 1513
A8: d01 | B8: 1 years age of the deceased | C8: {=H8+I8} -> 190 | D8: {=D120} -> 67 | E8: {=E120} -> 75 | F8: {=F120} -> 23 | G8: {=G120} -> 25 | H8: {=E8+D8} -> 142 | I8: {=G8+F8} -> 48 | J8: {=D8+F8} -> 90 | K8: {=E8+G8} -> 100
A9: d02 | B9: 2 years age of the deceased | C9: {=H9+I9} -> 134 | D9: {=D121} -> 42 | E9: {=E121} -> 58 | F9: {=F121} -> 15 | G9: {=G121} -> 19 | H9: {=E9+D9} -> 100 | I9: {=G9+F9} -> 34 | J9: {=D9+F9} -> 57 | K9: {=E9+G9} -> 77
A10: d03 | B10: 3 years age of the deceased | C10: {=H10+I10} -> 87 | D10: {=D122} -> 23 | E10: {=E122} -> 42 | F10: {=F122} -> 8 | G10: {=G122} -> 14 | H10: {=E10+D10} -> 65 | I10: {=G10+F10} -> 22 | J10: {=D10+F10} -> 31 | K10: {=E10+G10} -> 56
A11: d04 | B11: 4 years age of the deceased | C11: {=H11+I11} -> 98 | D11: {=D123} -> 31 | E11: {=E123} -> 42 | F11: {=F123} -> 11 | G11: {=G123} -> 14 | H11: {=E11+D11} -> 73 | I11: {=G11+F11} -> 25 | J11: {=D11+F11} -> 42 | K11: {=E11+G11} -> 56
A12: d05 | B12: 5 years age of the deceased | C12: {=H12+I12} -> 65 | D12: {=D124} -> 23 | E12: {=E124} -> 26 | F12: {=F124} -> 8 | G12: {=G124} -> 8 | H12: {=E12+D12} -> 49 | I12: {=G12+F12} -> 16 | J12: {=D12+F12} -> 31 | K12: {=E12+G12} -> 34
A13: d06 | B13: 6 years age of the deceased | C13: {=H13+I13} -> 66 | D13: {=D125} -> 21 | E13: {=E125} -> 29 | F13: {=F125} -> 7 | G13: {=G125} -> 9 | H13: {=E13+D13} -> 50 | I13: {=G13+F13} -> 16 | J13: {=D13+F13} -> 28 | K13: {=E13+G13} -> 38
A14: d07 | B14: 7 years age of the deceased | C14: {=H14+I14} -> 60 | D14: {=D126} -> 24 | E14: {=E126} -> 21 | F14: {=F126} -> 8 | G14: {=G126} -> 7 | H14: {=E14+D14} -> 45 | I14: {=G14+F14} -> 15 | J14: {=D14+F14} -> 32 | K14: {=E14+G14} -> 28
A15: d08 | B15: 8 years age of the deceased | C15: {=H15+I15} -> 65 | D15: {=D127} -> 22 | E15: {=E127} -> 26 | F15: {=F127} -> 8 | G15: {=G127} -> 9 | H15: {=E15+D15} -> 48 | I15: {=G15+F15} -> 17 | J15: {=D15+F15} -> 30 | K15: {=E15+G15} -> 35
A16: d09 | B16: 9 years age of the deceased | C16: {=H16+I16} -> 52 | D16: {=D128} -> 15 | E16: {=E128} -> 24 | F16: {=F128} -> 5 | G16: {=G128} -> 8 | H16: {=E16+D16} -> 39 | I16: {=G16+F16} -> 13 | J16: {=D16+F16} -> 20 | K16: {=E16+G16} -> 32
A17: d10 | B17: 10 years age of the deceased | C17: {=H17+I17} -> 74 | D17: {=D129} -> 28 | E17: {=E129} -> 28 | F17: {=F129} -> 9 | G17: {=G129} -> 9 | H17: {=E17+D17} -> 56 | I17: {=G17+F17} -> 18 | J17: {=D17+F17} -> 37 | K17: {=E17+G17} -> 37
A18: d11 | B18: 11 years age of the deceased | C18: {=H18+I18} -> 62 | D18: {=D130} -> 20 | E18: {=E130} -> 26 | F18: {=F130} -> 7 | G18: {=G130} -> 9 | H18: {=E18+D18} -> 46 | I18: {=G18+F18} -> 16 | J18: {=D18+F18} -> 27 | K18: {=E18+G18} -> 35
A19: d12 | B19: 12 years age of the deceased | C19: {=H19+I19} -> 74 | D19: {=D131} -> 19 | E19: {=E131} -> 36 | F19: {=F131} -> 7 | G19: {=G131} -> 12 | H19: {=E19+D19} -> 55 | I19: {=G19+F19} -> 19 | J19: {=D19+F19} -> 26 | K19: {=E19+G19} -> 48
... A106: d99 | B106: 99 years and older age of the deceased | C106: {=H106+I106} -> 21142 | D106: {=D218} -> 15113 | E106: {=E218} -> 2573 | F106: {=F218} -> 2283 | G106: {=G218} -> 1173 | H106: {=E106+D106} -> 17686 | I106: {=G106+F106} -> 3456 | J106: {=D106+F106} -> 17396 | K106: {=E106+G106} -> 3746
A107: dt | B107: Total | C107: {=SUM(C7:C106)} -> 642646 | D107: {=SUM(D7:D106)} -> 274220 | E107: {=SUM(E7:E106)} -> 258536 | F107: {=SUM(F7:F106)} -> 47991 | G107: {=SUM(G7:G106)} -> 62585 | H107: {=SUM(H7:H106)} -> 532756 | I107: {=SUM(I7:I106)} -> 110576 | J107: {=D107+F107} -> 322211 | K107: {=E107+G107} -> 321121
A109: ds | B109: Source of the data (verbal) | C109: {=IF(C110="","?",C110)&IF(C111="","","; downloaded "&C111)&IF(C112="","","; "&C112)} -> https://ec.europa.eu/eurostat/databrowser/view/demo_magec; downloaded 2026-05-22
B110: URLs, where the data was found | C110: https://ec.europa.eu/eurostat/databrowser/view/demo_magec
B111: Date, when the data was downloaded | C111: 2026-05-22
B112: Manual remarks (not for AI!)
B113: Remarks of the AI (e.g. calculation) | C113: Sterbefälle aus Eurostat demo_magec 2024 (geo=FR, Einzelalter × Sex). Total 2024 ≈ 643,332. NAT/MIG-Split (CLAUDE.md §Sterbe): anteilig zur calibrated Pop-Altersstruktur Native/Migrant pro Alter × Sex (einheitliche Sterbetafel, gleiche Mortalität für Native und Migrant). Modellannahme: Healthy-Migrant-Effekt nicht modelliert (CLAUDE.md-konform; in Realität haben Migranten jüngerer Alter günstigere Sterberaten).
B114: Internal remarks
B116: ✏️ | C116: Enter your data below and make sure that you adjust the formulas above, if necessary. If calculations are necessary, use the fields below for it and use formulas in the area above, to fill in the fields above exactly as intended.
B117: Deaths | C117: Calculation of the deaths
B119: 0 years | D119: 891 | E119: 1141 | F119: 306 | G119: 372
B120: 1 years | D120: 67 | E120: 75 | F120: 23 | G120: 25
B121: 2 years | D121: 42 | E121: 58 | F121: 15 | G121: 19
B122: 3 years | D122: 23 | E122: 42 | F122: 8 | G122: 14
B123: 4 years | D123: 31 | E123: 42 | F123: 11 | G123: 14
B124: 5 years | D124: 23 | E124: 26 | F124: 8 | G124: 8
B125: 6 years | D125: 21 | E125: 29 | F125: 7 | G125: 9
B126: 7 years | D126: 24 | E126: 21 | F126: 8 | G126: 7
B127: 8 years | D127: 22 | E127: 26 | F127: 8 | G127: 9
B128: 9 years | D128: 15 | E128: 24 | F128: 5 | G128: 8
B129: 10 years | D129: 28 | E129: 28 | F129: 9 | G129: 9
B130: 11 years | D130: 20 | E130: 26 | F130: 7 | G130: 9
...

Sheet migration
A1: migration
C2: aa | D2: nf | E2: nm | F2: mf | G2: mm | H2: na | I2: ma | J2: af | K2: am
B3: {=overview!C11&" / "&overview!C12} -> FR / France | C3: All | D3: Native Female | E3: Native Male | F3: Migrant Female | G3: Migrant Male | H3: Utility Native Male + Female | I3: Utility Migrant Male + Female | J3: Utility All Female | K3: Utility All Male | L3: Utility Other
B4: ⚠️ | C4: Do not add or delete lines until the next dark grey row below! The fields below are the fields used in other sheets and in the calculation. The address of these fields and their contents must remain always the same, so we can add calculations later!
B5: Migration balance | C5: This is the total of immigrations (into the country) minus emigration (out of the country)
B7: Year of the last migration numbers | C7: 2024
A9: ma | B9: Avarage migration balance (10 years) | C9: {=H9+I9} -> 126035.2 | D9: {=D199-D286} -> -36574.7 | E9: {=E199-E286} -> -33925 | F9: {=F199-F286} -> 99975.4 | G9: {=G199-G286} -> 96559.5 | H9: {=E9+D9} -> -70499.7 | I9: {=G9+F9} -> 196534.9 | J9: {=D9+F9} -> 63400.7 | K9: {=E9+G9} -> 62634.5
A11: m00 | B11: 0 years | C11: {=H11+I11} -> 0 | D11: {=D$9*$L11} -> 0 | E11: {=E$9*$L11} -> 0 | F11: {=F$9*$L11} -> 0 | G11: {=G$9*$L11} -> 0 | H11: {=E11+D11} -> 0 | I11: {=G11+F11} -> 0 | J11: {=D11+F11} -> 0 | K11: {=E11+G11} -> 0
A12: m01 | B12: 1 years | C12: {=H12+I12} -> 0 | D12: {=D$9*$L12} -> 0 | E12: {=E$9*$L12} -> 0 | F12: {=F$9*$L12} -> 0 | G12: {=G$9*$L12} -> 0 | H12: {=E12+D12} -> 0 | I12: {=G12+F12} -> 0 | J12: {=D12+F12} -> 0 | K12: {=E12+G12} -> 0
A13: m02 | B13: 2 years | C13: {=H13+I13} -> 0 | D13: {=D$9*$L13} -> 0 | E13: {=E$9*$L13} -> 0 | F13: {=F$9*$L13} -> 0 | G13: {=G$9*$L13} -> 0 | H13: {=E13+D13} -> 0 | I13: {=G13+F13} -> 0 | J13: {=D13+F13} -> 0 | K13: {=E13+G13} -> 0
A14: m03 | B14: 3 years | C14: {=H14+I14} -> 0 | D14: {=D$9*$L14} -> 0 | E14: {=E$9*$L14} -> 0 | F14: {=F$9*$L14} -> 0 | G14: {=G$9*$L14} -> 0 | H14: {=E14+D14} -> 0 | I14: {=G14+F14} -> 0 | J14: {=D14+F14} -> 0 | K14: {=E14+G14} -> 0
A15: m04 | B15: 4 years | C15: {=H15+I15} -> 0 | D15: {=D$9*$L15} -> 0 | E15: {=E$9*$L15} -> 0 | F15: {=F$9*$L15} -> 0 | G15: {=G$9*$L15} -> 0 | H15: {=E15+D15} -> 0 | I15: {=G15+F15} -> 0 | J15: {=D15+F15} -> 0 | K15: {=E15+G15} -> 0
A16: m05 | B16: 5 years | C16: {=H16+I16} -> 15.71819 | D16: {=D$9*$L16} -> -4.5613296 | E16: {=E$9*$L16} -> -4.2308783 | F16: {=F$9*$L16} -> 12.468202 | G16: {=G$9*$L16} -> 12.042196 | H16: {=E16+D16} -> -8.7922079 | I16: {=G16+F16} -> 24.510398 | J16: {=D16+F16} -> 7.9068725 | K16: {=E16+G16} -> 7.8113176 | L16: 0.0001247127
A17: m06 | B17: 6 years | C17: {=H17+I17} -> 25.651831 | D17: {=D$9*$L17} -> -7.4440158 | E17: {=E$9*$L17} -> -6.9047247 | F17: {=F$9*$L17} -> 20.347903 | G17: {=G$9*$L17} -> 19.652668 | H17: {=E17+D17} -> -14.34874 | I17: {=G17+F17} -> 40.000571 | J17: {=D17+F17} -> 12.903887 | K17: {=E17+G17} -> 12.747943 | L17: 0.0002035291
A18: m07 | B18: 7 years | C18: {=H18+I18} -> 41.017652 | D18: {=D$9*$L18} -> -11.90309 | E18: {=E$9*$L18} -> -11.040756 | F18: {=F$9*$L18} -> 32.536594 | G18: {=G$9*$L18} -> 31.424903 | H18: {=E18+D18} -> -22.943845 | I18: {=G18+F18} -> 63.961497 | J18: {=D18+F18} -> 20.633504 | K18: {=E18+G18} -> 20.384147 | L18: 0.000325446
A19: m08 | B19: 8 years | C19: {=H19+I19} -> 64.262878 | D19: {=D$9*$L19} -> -18.648723 | E19: {=E$9*$L19} -> -17.297693 | F19: {=F$9*$L19} -> 50.975497 | G19: {=G$9*$L19} -> 49.233796 | H19: {=E19+D19} -> -35.946415 | I19: {=G19+F19} -> 100.20929 | J19: {=D19+F19} -> 32.326774 | K19: {=E19+G19} -> 31.936104 | L19: 0.0005098804
A20: m09 | B20: 9 years | C20: {=H20+I20} -> 98.647562 | D20: {=D$9*$L20} -> -28.626963 | E20: {=E$9*$L20} -> -26.553047 | F20: {=F$9*$L20} -> 78.250596 | G20: {=G$9*$L20} -> 75.576976 | H20: {=E20+D20} -> -55.180009 | I20: {=G20+F20} -> 153.82757 | J20: {=D20+F20} -> 49.623633 | K20: {=E20+G20} -> 49.023929 | L20: 0.0007826985
A21: m10 | B21: 10 years | C21: {=H21+I21} -> 148.37113 | D21: {=D$9*$L21} -> -43.056461 | E21: {=E$9*$L21} -> -39.937182 | F21: {=F$9*$L21} -> 117.69302 | G21: {=G$9*$L21} -> 113.67176 | H21: {=E21+D21} -> -82.993643 | I21: {=G21+F21} -> 231.36478 | J21: {=D21+F21} -> 74.636559 | K21: {=E21+G21} -> 73.734574 | L21: 0.0011772198
A22: m11 | B22: 11 years | C22: {=H22+I22} -> 218.64992 | D22: {=D$9*$L22} -> -63.450967 | E22: {=E$9*$L22} -> -58.854182 | F22: {=F$9*$L22} -> 173.44054 | G22: {=G$9*$L22} -> 167.51453 | H22: {=E22+D22} -> -122.30515 | I22: {=G22+F22} -> 340.95507 | J22: {=D22+F22} -> 109.98958 | K22: {=E22+G22} -> 108.66035 | L22: 0.0017348322
A23: m12 | B23: 12 years | C23: {=H23+I23} -> 315.70835 | D23: {=D$9*$L23} -> -91.616771 | E23: {=E$9*$L23} -> -84.979479 | F23: {=F$9*$L23} -> 250.43058 | G23: {=G$9*$L23} -> 241.87402 | H23: {=E23+D23} -> -176.59625 | I23: {=G23+F23} -> 492.30459 | J23: {=D23+F23} -> 158.81381 | K23: {=E23+G23} -> 156.89454 | L23: 0.002504922
A24: m13 | B24: 13 years | C24: {=H24+I24} -> 446.6421 | D24: {=D$9*$L24} -> -129.613 | E24: {=E$9*$L24} -> -120.22303 | F24: {=F$9*$L24} -> 354.29168 | G24: {=G$9*$L24} -> 342.18646 | H24: {=E24+D24} -> -249.83603 | I24: {=G24+F24} -> 696.47814 | J24: {=D24+F24} -> 224.67868 | K24: {=E24+G24} -> 221.96343 | L24: 0.0035437886
A25: m14 | B25: 14 years | C25: {=H25+I25} -> 619.11326 | D25: {=D$9*$L25} -> -179.66316 | E25: {=E$9*$L25} -> -166.64723 | F25: {=F$9*$L25} -> 491.10166 | G25: {=G$9*$L25} -> 474.32199 | H25: {=E25+D25} -> -346.31039 | I25: {=G25+F25} -> 965.42365 | J25: {=D25+F25} -> 311.4385 | K25: {=E25+G25} -> 307.67476 | L25: 0.004912225
A26: m15 | B26: 15 years | C26: {=H26+I26} -> 840.84781 | D26: {=D$9*$L26} -> -244.00926 | E26: {=E$9*$L26} -> -226.33171 | F26: {=F$9*$L26} -> 666.98903 | G26: {=G$9*$L26} -> 644.19975 | H26: {=E26+D26} -> -470.34097 | I26: {=G26+F26} -> 1311.1888 | J26: {=D26+F26} -> 422.97977 | K26: {=E26+G26} -> 417.86804 | L26: 0.0066715315
A27: m16 | B27: 16 years | C27: {=H27+I27} -> 1118.9264 | D27: {=D$9*$L27} -> -324.7061 | E27: {=E$9*$L27} -> -301.18236 | F27: {=F$9*$L27} -> 887.57043 | G27: {=G$9*$L27} -> 857.24446 | H27: {=E27+D27} -> -625.88846 | I27: {=G27+F27} -> 1744.8149 | J27: {=D27+F27} -> 562.86433 | K27: {=E27+G27} -> 556.06209 | L27: 0.0088778883
... A65: m54 | B65: 54 years | C65: {=H65+I65} -> 15.71819 | D65: {=D$9*$L65} -> -4.5613296 | E65: {=E$9*$L65} -> -4.2308783 | F65: {=F$9*$L65} -> 12.468202 | G65: {=G$9*$L65} -> 12.042196 | H65: {=E65+D65} -> -8.7922079 | I65: {=G65+F65} -> 24.510398 | J65: {=D65+F65} -> 7.9068725 | K65: {=E65+G65} -> 7.8113176 | L65: 0.0001247127
A66: m55 | B66: 55 years | C66: {=H66+I66} -> 0 | D66: {=D$9*$L66} -> 0 | E66: {=E$9*$L66} -> 0 | F66: {=F$9*$L66} -> 0 | G66: {=G$9*$L66} -> 0 | H66: {=E66+D66} -> 0 | I66: {=G66+F66} -> 0 | J66: {=D66+F66} -> 0 | K66: {=E66+G66} -> 0
A67: m56 | B67: 56 years | C67: {=H67+I67} -> 0 | D67: {=D$9*$L67} -> 0 | E67: {=E$9*$L67} -> 0 | F67: {=F$9*$L67} -> 0 | G67: {=G$9*$L67} -> 0 | H67: {=E67+D67} -> 0 | I67: {=G67+F67} -> 0 | J67: {=D67+F67} -> 0 | K67: {=E67+G67} -> 0
A68: m57 | B68: 57 years | C68: {=H68+I68} -> 0 | D68: {=D$9*$L68} -> 0 | E68: {=E$9*$L68} -> 0 | F68: {=F$9*$L68} -> 0 | G68: {=G$9*$L68} -> 0 | H68: {=E68+D68} -> 0 | I68: {=G68+F68} -> 0 | J68: {=D68+F68} -> 0 | K68: {=E68+G68} -> 0
A69: m58 | B69: 58 years | C69: {=H69+I69} -> 0 | D69: {=D$9*$L69} -> 0 | E69: {=E$9*$L69} -> 0 | F69: {=F$9*$L69} -> 0 | G69: {=G$9*$L69} -> 0 | H69: {=E69+D69} -> 0 | I69: {=G69+F69} -> 0 | J69: {=D69+F69} -> 0 | K69: {=E69+G69} -> 0
A70: m59 | B70: 59 years | C70: {=H70+I70} -> 0 | D70: {=D$9*$L70} -> 0 | E70: {=E$9*$L70} -> 0 | F70: {=F$9*$L70} -> 0 | G70: {=G$9*$L70} -> 0 | H70: {=E70+D70} -> 0 | I70: {=G70+F70} -> 0 | J70: {=D70+F70} -> 0 | K70: {=E70+G70} -> 0
A71: m60 | B71: 60 years | C71: {=H71+I71} -> 0 | D71: {=D$9*$L71} -> 0 | E71: {=E$9*$L71} -> 0 | F71: {=F$9*$L71} -> 0 | G71: {=G$9*$L71} -> 0 | H71: {=E71+D71} -> 0 | I71: {=G71+F71} -> 0 | J71: {=D71+F71} -> 0 | K71: {=E71+G71} -> 0
A72: m61 | B72: 61 years | C72: {=H72+I72} -> 0 | D72: {=D$9*$L72} -> 0 | E72: {=E$9*$L72} -> 0 | F72: {=F$9*$L72} -> 0 | G72: {=G$9*$L72} -> 0 | H72: {=E72+D72} -> 0 | I72: {=G72+F72} -> 0 | J72: {=D72+F72} -> 0 | K72: {=E72+G72} -> 0
A73: m62 | B73: 62 years | C73: {=H73+I73} -> 0 | D73: {=D$9*$L73} -> 0 | E73: {=E$9*$L73} -> 0 | F73: {=F$9*$L73} -> 0 | G73: {=G$9*$L73} -> 0 | H73: {=E73+D73} -> 0 | I73: {=G73+F73} -> 0 | J73: {=D73+F73} -> 0 | K73: {=E73+G73} -> 0
A74: m63 | B74: 63 years | C74: {=H74+I74} -> 0 | D74: {=D$9*$L74} -> 0 | E74: {=E$9*$L74} -> 0 | F74: {=F$9*$L74} -> 0 | G74: {=G$9*$L74} -> 0 | H74: {=E74+D74} -> 0 | I74: {=G74+F74} -> 0 | J74: {=D74+F74} -> 0 | K74: {=E74+G74} -> 0
A75: m64 | B75: 64 years | C75: {=H75+I75} -> 0 | D75: {=D$9*$L75} -> 0 | E75: {=E$9*$L75} -> 0 | F75: {=F$9*$L75} -> 0 | G75: {=G$9*$L75} -> 0 | H75: {=E75+D75} -> 0 | I75: {=G75+F75} -> 0 | J75: {=D75+F75} -> 0 | K75: {=E75+G75} -> 0
A76: m65 | B76: 65 years | C76: {=H76+I76} -> 0 | D76: {=D$9*$L76} -> 0 | E76: {=E$9*$L76} -> 0 | F76: {=F$9*$L76} -> 0 | G76: {=G$9*$L76} -> 0 | H76: {=E76+D76} -> 0 | I76: {=G76+F76} -> 0 | J76: {=D76+F76} -> 0 | K76: {=E76+G76} -> 0
A77: m66 | B77: 66 years | C77: {=H77+I77} -> 0 | D77: {=D$9*$L77} -> 0 | E77: {=E$9*$L77} -> 0 | F77: {=F$9*$L77} -> 0 | G77: {=G$9*$L77} -> 0 | H77: {=E77+D77} -> 0 | I77: {=G77+F77} -> 0 | J77: {=D77+F77} -> 0 | K77: {=E77+G77} -> 0
... A110: m99 | B110: 99 years and older | C110: {=H110+I110} -> 0 | D110: {=D$9*$L110} -> 0 | E110: {=E$9*$L110} -> 0 | F110: {=F$9*$L110} -> 0 | G110: {=G$9*$L110} -> 0 | H110: {=E110+D110} -> 0 | I110: {=G110+F110} -> 0 | J110: {=D110+F110} -> 0 | K110: {=E110+G110} -> 0
A111: mt | B111: Total | C111: {=SUM(C11:C110)} -> 126035.2 | D111: {=SUM(D11:D110)} -> -36574.7 | E111: {=SUM(E11:E110)} -> -33925 | F111: {=SUM(F11:F110)} -> 99975.4 | G111: {=SUM(G11:G110)} -> 96559.5 | H111: {=SUM(H11:H110)} -> -70499.7 | I111: {=SUM(I11:I110)} -> 196534.9 | J111: {=D111+F111} -> 63400.7 | K111: {=E111+G111} -> 62634.5
A113: ms | B113: Source of the data (verbal) | C113: {=IF(C114="","?",C114)&IF(C115="","","; downloaded "&C115)&IF(C116="","","; "&C116)} -> Enter URLs here, if you have multiple URLs seperate them with a comma; downloaded yyyy-MM-dd; we used the 10-year average number of the migration balance (2015-2024); the numbers are binomially distributed between the age of 5 and 54
...

Sheet origin
A1: origin
C2: aa | D2: nf | E2: nm | F2: mf | G2: mm | H2: na | I2: ma | J2: af | K2: am
B3: {=overview!C11&" / "&overview!C12} -> FR / France | C3: All | D3: Native Female | E3: Native Male | F3: Migrant Female | G3: Migrant Male | H3: Utility Native Male + Female | I3: Utility Migrant Male + Female | J3: Utility All Female | K3: Utility All Male | L3: Utility Other
B4: ✏️ | C4: Enter your data below and make sure that you adjust the formulas above, if necessary. If calculations are necessary, use the fields below for it and use formulas in the area above, to fill in the fields above exactly as intended.
B5: Origin of Migrants | C5: This table contains the countries the current migrants come from.
B7: Year of the numbers | C7: 2025
B9: Europe
A10: c1ad | B10: Andorra | C10: AD | I10: {=G10+F10} -> 0
A11: c1al | B11: Albania | C11: AL | I11: {=G11+F11} -> 0
A12: c1at | B12: Austria | C12: AT | F12: 4675 | G12: 2914 | I12: {=G12+F12} -> 7589
A13: c1ax | B13: Åland Islands | C13: AX | I13: {=G13+F13} -> 0
A14: c1ba | B14: Bosnia and Herzegovina | C14: BA | I14: {=G14+F14} -> 0
A15: c1be | B15: Belgium | C15: BE | F15: 72208 | G15: 62016 | I15: {=G15+F15} -> 134224
A16: c1bg | B16: Bulgaria | C16: BG | F16: 13533 | G16: 11206 | I16: {=G16+F16} -> 24739
A17: c1by | B17: Belarus | C17: BY | I17: {=G17+F17} -> 0
A18: c1ch | B18: Switzerland | C18: CH | I18: {=G18+F18} -> 0
A19: c1cz | B19: Czechia[i] | C19: CZ | F19: 4396 | G19: 2373 | I19: {=G19+F19} -> 6769
A20: c1de | B20: Germany | C20: DE | F20: 83441 | G20: 65987 | I20: {=G20+F20} -> 149428
A21: c1dk | B21: Denmark | C21: DK | F21: 2267 | G21: 1676 | I21: {=G21+F21} -> 3943
A22: c1ee | B22: Estonia | C22: EE | F22: 802 | G22: 373 | I22: {=G22+F22} -> 1175
A23: c1es | B23: Spain | C23: ES | F23: 107799 | G23: 87546 | I23: {=G23+F23} -> 195345
A24: c1fi | B24: Finland | C24: FI | F24: 2304 | G24: 782 | I24: {=G24+F24} -> 3086
A25: c1fo | B25: Faroe Islands (the) | C25: FO | I25: {=G25+F25} -> 0
A26: c1fr | B26: France | C26: FR | I26: {=G26+F26} -> 0
A27: c1gb | B27: United Kingdom of Great Britain and Northern Ireland (the) | C27: GB | I27: {=G27+F27} -> 0
A28: c1gg | B28: Guernsey | C28: GG | I28: {=G28+F28} -> 0
A29: c1gi | B29: Gibraltar | C29: GI | I29: {=G29+F29} -> 0
A30: c1gr | B30: Greece | C30: GR | F30: 6906 | G30: 5916 | I30: {=G30+F30} -> 12822
A31: c1hr | B31: Croatia | C31: HR | F31: 3653 | G31: 2770 | I31: {=G31+F31} -> 6423
A32: c1hu | B32: Hungary | C32: HU | F32: 5265 | G32: 3268 | I32: {=G32+F32} -> 8533
A33: c1ie | B33: Ireland | C33: IE | F33: 4531 | G33: 3849 | I33: {=G33+F33} -> 8380
A34: c1im | B34: Isle of Man | C34: IM | I34: {=G34+F34} -> 0
A35: c1is | B35: Iceland | C35: IS | I35: {=G35+F35} -> 0
A36: c1it | B36: Italy | C36: IT | F36: 113238 | G36: 109719 | I36: {=G36+F36} -> 222957
A37: c1je | B37: Jersey | C37: JE | I37: {=G37+F37} -> 0
A38: c1li | B38: Liechtenstein | C38: LI | I38: {=G38+F38} -> 0
A39: c1lt | B39: Lithuania | C39: LT | F39: 1992 | G39: 1148 | I39: {=G39+F39} -> 3140
A40: c1lu | B40: Luxembourg | C40: LU | F40: 8448 | G40: 8488 | I40: {=G40+F40} -> 16936
A41: c1lv | B41: Latvia | C41: LV | F41: 1726 | G41: 1010 | I41: {=G41+F41} -> 2736
A42: c1mc | B42: Monaco | C42: MC | I42: {=G42+F42} -> 0
...

Sheet patria
A1: patria
C2: aa | D2: nf | E2: nm | F2: mf | G2: mm | H2: na | I2: ma | J2: af | K2: am
B3: {=overview!C11&" / "&overview!C12} -> FR / France | C3: All | D3: Native Female | E3: Native Male | F3: Migrant Female | G3: Migrant Male | H3: Utility Native Male + Female | I3: Utility Migrant Male + Female | J3: Utility All Female | K3: Utility All Male | L3: Utility Other
B4: ✏️ | C4: Enter your data below and make sure that you adjust the formulas above, if necessary. If calculations are necessary, use the fields below for it and use formulas in the area above, to fill in the fields above exactly as intended.
B5: Naturalisation | C5: Fill in the numbers of people being naturalized in the specified year. This is not relevant for the calculation of version 1 but it is important for future versions.
B7: Year of the last migration numbers | C7: 2025
B9: {=$B10-1} -> 1950 | C9: {=I9} -> 43790 | I9: 43790
B10: {=$B11-1} -> 1951 | C10: {=I10} -> 25257 | I10: 25257
B11: {=$B12-1} -> 1952 | C11: {=I11} -> 28139 | I11: 28139
B12: {=$B13-1} -> 1953 | C12: {=I12} -> 34824 | I12: 34824
B13: {=$B14-1} -> 1954 | C13: {=I13} -> 39308 | I13: 39308
B14: {=$B15-1} -> 1955 | C14: {=I14} -> 44972 | I14: 44972
B15: {=$B16-1} -> 1956 | C15: {=I15} -> 38040 | I15: 38040
B16: {=$B17-1} -> 1957 | C16: {=I16} -> 36890 | I16: 36890
B17: {=$B18-1} -> 1958 | C17: {=I17} -> 34452 | I17: 34452
B18: {=$B19-1} -> 1959 | C18: {=I18} -> 34098 | I18: 34098
B19: {=$B20-1} -> 1960 | C19: {=I19} -> 29683 | I19: 29683
B20: {=$B21-1} -> 1961 | C20: {=I20} -> 25954 | I20: 25954
... B56: {=$B57-1} -> 1997 | C56: {=I56} -> 116286 | I56: 116286
B57: {=$B58-1} -> 1998 | C57: {=I57} -> 0 | I57: {=G57+F57} -> 0
B58: {=$B59-1} -> 1999 | C58: {=I58} -> 0 | I58: {=G58+F58} -> 0
B59: {=$B60-1} -> 2000 | C59: {=I59} -> 0 | I59: {=G59+F59} -> 0
B60: {=$B61-1} -> 2001 | C60: {=I60} -> 0 | I60: {=G60+F60} -> 0
B61: {=$B62-1} -> 2002 | C61: {=I61} -> 0 | I61: {=G61+F61} -> 0
B62: {=$B63-1} -> 2003 | C62: {=I62} -> 0 | I62: {=G62+F62} -> 0
B63: {=$B64-1} -> 2004 | C63: {=I63} -> 0 | I63: {=G63+F63} -> 0
B64: {=$B65-1} -> 2005 | C64: {=I64} -> 0 | I64: {=G64+F64} -> 0
B65: {=$B66-1} -> 2006 | C65: {=I65} -> 0 | I65: {=G65+F65} -> 0
B66: {=$B67-1} -> 2007 | C66: {=I66} -> 0 | I66: {=G66+F66} -> 0
B67: {=$B68-1} -> 2008 | C67: {=I67} -> 137452 | F67: 69749 | G67: 67703 | I67: {=G67+F67} -> 137452
B68: {=$B69-1} -> 2009 | C68: {=I68} -> 135852 | F68: 69358 | G68: 66494 | I68: {=G68+F68} -> 135852
B69: {=$B70-1} -> 2010 | C69: {=I69} -> 143261 | F69: 73087 | G69: 70174 | I69: {=G69+F69} -> 143261
B70: {=$B71-1} -> 2011 | C70: {=I70} -> 114569 | F70: 59075 | G70: 55494 | I70: {=G70+F70} -> 114569
B71: {=$B72-1} -> 2012 | C71: {=I71} -> 96051 | F71: 49413 | G71: 46638 | I71: {=G71+F71} -> 96051
B72: {=$B73-1} -> 2013 | C72: {=I72} -> 97276 | F72: 49550 | G72: 47726 | I72: {=G72+F72} -> 97276
B73: {=$B74-1} -> 2014 | C73: {=I73} -> 105613 | F73: 53939 | G73: 51674 | I73: {=G73+F73} -> 105613
B74: {=$B75-1} -> 2015 | C74: {=I74} -> 113608 | F74: 58601 | G74: 55007 | I74: {=G74+F74} -> 113608
B75: {=$B76-1} -> 2016 | C75: {=I75} -> 119152 | F75: 61272 | G75: 57880 | I75: {=G75+F75} -> 119152
B76: {=$B77-1} -> 2017 | C76: {=I76} -> 114274 | F76: 58676 | G76: 55598 | I76: {=G76+F76} -> 114274
B77: {=$B78-1} -> 2018 | C77: {=I77} -> 110014 | F77: 57244 | G77: 52770 | I77: {=G77+F77} -> 110014
...

Sheet export
A1: export
C2: aa | D2: nf | E2: nm | F2: mf | G2: mm | H2: na | I2: ma | J2: af | K2: am
B3: {=overview!C11&" / "&overview!C12} -> FR / France | C3: All | D3: Native Female | E3: Native Male | F3: Migrant Female | G3: Migrant Male | H3: Utility Native Male + Female | I3: Utility Migrant Male + Female | J3: Utility All Female | K3: Utility All Male | L3: Utility Other
B4: ⚠️ | C4: Do not change this sheet!
B5: Overview
A6: {=overview!A11} -> na | C6: {=overview!C11} -> FR
A7: {=overview!A12} -> nn | C7: {=overview!C12} -> France
A8: {=overview!$A49} -> i | C8: {=overview!C49} -> MH i.w.S. nach INSEE-Definition: immigré (personne née étrangère à l'étranger et résidant en France; bleibt immigré auch nach Erwerb der frz. StAng) + descendant d'immigrés (en France geboren, mit mindestens einem immigré-Elternteil). 3. Generation nicht modelliert (V2-Thema TeO2).
A9: {=overview!$A51} -> is | C9: {=overview!C51} -> https://www.insee.fr/fr/metadonnees/definition/c1676; downloaded 2026-05-22
A10: {=overview!$A60} -> l | C10: {=overview!C60} -> 82.933348 | D10: {=overview!D60} -> 85.7 | E10: {=overview!E60} -> 80 | F10: {=overview!F60} -> 85.7 | G10: {=overview!G60} -> 80 | H10: {=overview!H60} -> 82.946088 | I10: {=overview!I60} -> 82.887624 | J10: {=overview!J60} -> 85.7 | K10: {=overview!K60} -> 80
A11: {=overview!$A62} -> ls | C11: {=overview!C62} -> https://www.insee.fr/fr/statistiques/8719824, https://www.insee.fr/fr/statistiques/8313953; downloaded 2026-05-22
B13: Population
A14: {=population!$A7} -> py | C14: {=population!C7} -> 2025
A15: {=population!$A9} -> p00 | C15: {=population!C9} -> 613930 | D15: {=population!D9} -> 223160 | E15: {=population!E9} -> 236773 | F15: {=population!F9} -> 76749 | G15: {=population!G9} -> 77248 | H15: {=population!H9} -> 459933 | I15: {=population!I9} -> 153997 | J15: {=population!J9} -> 299909 | K15: {=population!K9} -> 314021
A16: {=population!$A10} -> p01 | C16: {=population!C10} -> 633124 | D16: {=population!D10} -> 230533 | E16: {=population!E10} -> 243780 | F16: {=population!F10} -> 79161 | G16: {=population!G10} -> 79650 | H16: {=population!H10} -> 474313 | I16: {=population!I10} -> 158811 | J16: {=population!J10} -> 309694 | K16: {=population!K10} -> 323430
A17: {=population!$A11} -> p02 | C17: {=population!C11} -> 680945 | D17: {=population!D11} -> 247647 | E17: {=population!E11} -> 262491 | F17: {=population!F11} -> 85131 | G17: {=population!G11} -> 85676 | H17: {=population!H11} -> 510138 | I17: {=population!I11} -> 170807 | J17: {=population!J11} -> 332778 | K17: {=population!K11} -> 348167
A18: {=population!$A12} -> p03 | C18: {=population!C12} -> 707427 | D18: {=population!D12} -> 258010 | E18: {=population!E12} -> 271968 | F18: {=population!F12} -> 88466 | G18: {=population!G12} -> 88983 | H18: {=population!H12} -> 529978 | I18: {=population!I12} -> 177449 | J18: {=population!J12} -> 346476 | K18: {=population!K12} -> 360951
A19: {=population!$A13} -> p04 | C19: {=population!C13} -> 711837 | D19: {=population!D13} -> 259140 | E19: {=population!E13} -> 274142 | F19: {=population!F13} -> 89001 | G19: {=population!G13} -> 89554 | H19: {=population!H13} -> 533282 | I19: {=population!I13} -> 178555 | J19: {=population!J13} -> 348141 | K19: {=population!K13} -> 363696
A20: {=population!$A14} -> p05 | C20: {=population!C14} -> 738384 | D20: {=population!D14} -> 267392 | E20: {=population!E14} -> 285777 | F20: {=population!F14} -> 92274 | G20: {=population!G14} -> 92941 | H20: {=population!H14} -> 553169 | I20: {=population!I14} -> 185215 | J20: {=population!J14} -> 359666 | K20: {=population!K14} -> 378718
A21: {=population!$A15} -> p06 | C21: {=population!C15} -> 747315 | D21: {=population!D15} -> 271396 | E21: {=population!E15} -> 288465 | F21: {=population!F15} -> 93415 | G21: {=population!G15} -> 94039 | H21: {=population!H15} -> 559861 | I21: {=population!I15} -> 187454 | J21: {=population!J15} -> 364811 | K21: {=population!K15} -> 382504
A22: {=population!$A16} -> p07 | C22: {=population!C16} -> 762141 | D22: {=population!D16} -> 274735 | E22: {=population!E16} -> 296232 | F22: {=population!F16} -> 95201 | G22: {=population!G16} -> 95973 | H22: {=population!H16} -> 570967 | I22: {=population!I16} -> 191174 | J22: {=population!J16} -> 369936 | K22: {=population!K16} -> 392205
A23: {=population!$A17} -> p08 | C23: {=population!C17} -> 783490 | D23: {=population!D17} -> 283507 | E23: {=population!E17} -> 303454 | F23: {=population!F17} -> 97903 | G23: {=population!G17} -> 98626 | H23: {=population!H17} -> 586961 | I23: {=population!I17} -> 196529 | J23: {=population!J17} -> 381410 | K23: {=population!K17} -> 402080
A24: {=population!$A18} -> p09 | C24: {=population!C18} -> 805772 | D24: {=population!D18} -> 292809 | E24: {=population!E18} -> 310845 | F24: {=population!F18} -> 100729 | G24: {=population!G18} -> 101389 | H24: {=population!H18} -> 603654 | I24: {=population!I18} -> 202118 | J24: {=population!J18} -> 393538 | K24: {=population!K18} -> 412234
A25: {=population!$A19} -> p10 | C25: {=population!C19} -> 828311 | D25: {=population!D19} -> 301901 | E25: {=population!E19} -> 318639 | F25: {=population!F19} -> 103576 | G25: {=population!G19} -> 104195 | H25: {=population!H19} -> 620540 | I25: {=population!I19} -> 207771 | J25: {=population!J19} -> 405477 | K25: {=population!K19} -> 422834
A26: {=population!$A20} -> p11 | C26: {=population!C20} -> 834912 | D26: {=population!D20} -> 303966 | E26: {=population!E20} -> 321519 | F26: {=population!F20} -> 104390 | G26: {=population!G20} -> 105037 | H26: {=population!H20} -> 625485 | I26: {=population!I20} -> 209427 | J26: {=population!J20} -> 408356 | K26: {=population!K20} -> 426556
... A115: {=population!$A109} -> pt | C115: {=population!C109} -> 68882600 | D115: {=population!D109} -> 27844155 | E115: {=population!E109} -> 26027855 | F115: {=population!F109} -> 7604375 | G115: {=population!G109} -> 7406215 | H115: {=population!H109} -> 53872010 | I115: {=population!I109} -> 15010590 | J115: {=population!J109} -> 35448530 | K115: {=population!K109} -> 33434070
A116: {=population!$A111} -> ps | C116: {=population!C111} -> https://ec.europa.eu/eurostat/databrowser/view/demo_pjan, https://www.insee.fr/fr/statistiques/8582067, https://www.insee.fr/fr/statistiques/4187125; downloaded 2026-05-22
B118: Births
A119: {=births!$A7} -> f | H119: {=births!D7} -> 1.7 | I119: {=births!F7} -> 2.3
A120: {=births!$A11} -> f00 | C120: {=births!C11} -> 613930 | D120: {=births!D11} -> 207157.5 | E120: {=births!E11} -> 216905.15 | F120: {=births!F11} -> 92751.499 | G120: {=births!G11} -> 97115.854 | H120: {=births!H11} -> 424062.65 | I120: {=births!I11} -> 189867.35 | J120: {=births!J11} -> 299909 | K120: {=births!K11} -> 314021
A121: {=births!$A13} -> fs | C121: {=births!C13} -> https://www.insee.fr/fr/statistiques/6801884, https://www.insee.fr/fr/statistiques/6793238; downloaded 2026-05-22
A122: {=births!$A22} -> b15 | C122: {=births!C22} -> 362.33305 | D122: {=births!D22} -> 92.394558 | E122: {=births!E22} -> 96.742117 | F122: {=births!F22} -> 84.607613 | G122: {=births!G22} -> 88.588762 | H122: {=births!H22} -> 218 | I122: {=births!I22} -> 157 | J122: {=births!J22} -> 177.00217 | K122: {=births!K22} -> 185.33088
A123: {=births!$A23} -> b16 | C123: {=births!C23} -> 890.84872 | D123: {=births!D23} -> 264.89266 | E123: {=births!E23} -> 277.35699 | F123: {=births!F23} -> 170.29303 | G123: {=births!G23} -> 178.30604 | H123: {=births!H23} -> 625 | I123: {=births!I23} -> 316 | J123: {=births!J23} -> 435.18569 | K123: {=births!K23} -> 455.66303
A124: {=births!$A24} -> b17 | C124: {=births!C24} -> 1557.399 | D124: {=births!D24} -> 508.5939 | E124: {=births!E24} -> 532.52542 | F124: {=births!F24} -> 252.20613 | G124: {=births!G24} -> 264.07351 | H124: {=births!H24} -> 1200 | I124: {=births!I24} -> 468 | J124: {=births!J24} -> 760.80003 | K124: {=births!K24} -> 796.59892
A125: {=births!$A25} -> b18 | C125: {=births!C25} -> 2836.6336 | D125: {=births!D25} -> 971.83818 | E125: {=births!E25} -> 1017.5673 | F125: {=births!F25} -> 413.87673 | G125: {=births!G25} -> 433.3514 | H125: {=births!H25} -> 2293 | I125: {=births!I25} -> 768 | J125: {=births!J25} -> 1385.7149 | K125: {=births!K25} -> 1450.9187
A126: {=births!$A26} -> b19 | C126: {=births!C26} -> 5200.0258 | D126: {=births!D26} -> 1830.5142 | E126: {=births!E26} -> 1916.6477 | F126: {=births!F26} -> 709.73392 | G126: {=births!G26} -> 743.12994 | H126: {=births!H26} -> 4319 | I126: {=births!I26} -> 1317 | J126: {=births!J26} -> 2540.2481 | K126: {=births!K26} -> 2659.7777
A127: {=births!$A27} -> b20 | C127: {=births!C27} -> 7672.0205 | D127: {=births!D27} -> 2618.8348 | E127: {=births!E27} -> 2742.0621 | F127: {=births!F27} -> 1128.9997 | G127: {=births!G27} -> 1182.1239 | H127: {=births!H27} -> 6179 | I127: {=births!I27} -> 2095 | J127: {=births!J27} -> 3747.8344 | K127: {=births!K27} -> 3924.1861
A128: {=births!$A28} -> b21 | C128: {=births!C28} -> 10299.551 | D128: {=births!D28} -> 3482.5967 | E128: {=births!E28} -> 3646.4678 | F128: {=births!F28} -> 1548.8043 | G128: {=births!G28} -> 1621.6822 | H128: {=births!H28} -> 8217 | I128: {=births!I28} -> 2874 | J128: {=births!J28} -> 5031.4011 | K128: {=births!K28} -> 5268.15
A129: {=births!$A29} -> b22 | C129: {=births!C29} -> 12999.474 | D129: {=births!D29} -> 4495.9701 | E129: {=births!E29} -> 4707.5247 | F129: {=births!F29} -> 1854.3618 | G129: {=births!G29} -> 1941.6174 | H129: {=births!H29} -> 10608 | I129: {=births!I29} -> 3441 | J129: {=births!J29} -> 6350.3318 | K129: {=births!K29} -> 6649.1421
A130: {=births!$A30} -> b23 | C130: {=births!C30} -> 17040.549 | D130: {=births!D30} -> 5843.3201 | E130: {=births!E30} -> 6118.2733 | F130: {=births!F30} -> 2481.1048 | G130: {=births!G30} -> 2597.8513 | H130: {=births!H30} -> 13787 | I130: {=births!I30} -> 4604 | J130: {=births!J30} -> 8324.4248 | K130: {=births!K30} -> 8716.1246
...
