Workbook

Sheet overview
A1: overview
C2: aa | D2: nf | E2: nm | F2: mf | G2: mm | H2: na | I2: ma | J2: af | K2: am
B3: {=C11&" / "&C12} | C3: All | D3: Native Female | E3: Native Male | F3: Migrant Female | G3: Migrant Male | H3: Utility Native Male + Female | I3: Utility Migrant Male + Female | J3: Utility All Female | K3: Utility All Male | L3: Utility Other
B4: Information | C4: This column contains general values (like definitions and sources) | D4: This column is important for the correct calculation | E4: This column is important for the correct calculation | F4: This column is important for the correct calculation | G4: This column is important for the correct calculation | H4: This column only contains utilty values used to calculate the data on the left | I4: This column only contains utilty values used to calculate the data on the left | J4: This column only contains utilty values used to calculate the data on the left | K4: This column only contains utilty values used to calculate the data on the left | L4: This column only contains utilty values used to calculate the data on the left
B5: Editing this spreadsheet | C5: On a blue background, you can edit values and formulas
C6: On a green background, only change the formula (normally the formula should be right though)
C7: On a yellow background, don't change anything!
C8: On a dark grey background, you find important instructions
B10: Country
A11: na | B11: Acronym (e.g. "DE") | C11: NL
A12: nn | B12: Name | C12: Niederlande
A13: nd | B13: Date when the sheets were generated | C13: 2026-05-26 19:00
B15: Estimation | C15: This is an estimation of the tipping point
B17: Current population | C17: {=H17+I17} | D17: {=C34} | E17: pn, pm | H17: {='population'!H109} | I17: {='population'!I109}
B18: Gap native - migrant | C18: {=H17-I17} | D18: {=C18/C17}
B19: Birth / year according to population | H19: {='population'!H9} | I19: {='population'!I9}
B20: Birth / year according to fertility | H20: {='births'!H11} | I20: {='births'!I11}
B21: Birth / year used for estimation | D21: We prefer the number of births according to the fertility | H21: {=IF(ISNUMBER(H20),H20,H19)} | I21: {=IF(ISNUMBER(I20),I20,I19)}
B22: Deaths / year | H22: {=-'deaths'!H107} | I22: {=-'deaths'!I107}
B23: Migration balance / year | H23: {='migration'!H9} | I23: {='migration'!I9}
B24: Population delta / year | C24: {=I24-H24} | D24: {=C24/C17} | E24: dn, dm | H24: {=H21+H22+H23} | I24: {=I21+I22+I23}
B26: Years until 33% share of migrants | C26: {=(H$17-2*I$17)/(2*I$24-H$24)} | D26: y = (pn - 2*pm) / (2*dm - dn)
B27: Estimated tipping point for 33% share of migrants | C27: {=C$33+C26}
B28: Years until 50% share of migrants | C28: {=(H$17-I$17)/(I$24-H$24)} | D28: y = (pn - pm) / (dm - dn)
B29: Estimated tipping point for 50% share of migrants | C29: {=C$33+C28}
B31: Indicators | C31: This indicators are used to find differences between countries and thus show where the data collection might be wrong
B33: Year of the population numbers | C33: {='population'!C7}
B34: Share of migrant population | C34: {='population'!I109/'population'!C109} | D34: > 20% normally
B35: Births per 1 mio. women (15-49) | C35: {=I35/H35-1} | D35: > 30% normally | H35: {='births'!H11/'births'!D9*1000000} | I35: {='births'!I11/'births'!F9*1000000}
B36: Births per 1 mio. population | C36: {=I36/H36-1} | D36: > 50% normally due to younger migrant population | H36: {='births'!H11/'population'!H109*1000000} | I36: {='births'!I11/'population'!I109*1000000}
B37: Deaths per 1 mio. population | C37: {=I37/H37-1} | D37: < 0% normally due to younger migrant population | H37: {='deaths'!H$107/'population'!H$109*1000000} | I37: {='deaths'!I$107/'population'!I$109*1000000}
B38: Migration balance per 1 mio. of group | H38: {='migration'!H111/'population'!H109*1000000} | I38: {='migration'!I111/'population'!I109*1000000}
B39: Migration balance in % of population | H39: {='migration'!H111/'population'!C109} | I39: {='migration'!I111/'population'!D109}
B47: Migration Background | C47: How is the "Migration Background" defined in this country?
A49: i | B49: Definition of the 'migration background' | C49: MH i.w.S. nach CBS-Definition (seit Reform 16.02.2022): 'Persoon met een herkomst buiten Nederland' = Personen, die selbst im Ausland geboren wurden (1. Generation) ODER in den Niederlanden geboren wurden mit mindestens einem im Ausland geborenen Elternteil (2. Generation). 'Persoon met Nederlandse herkomst' (= Native) = in NL geboren mit beiden Eltern in NL geboren. 3. Generation (mit MH-Großeltern, aber beiden Eltern in NL geboren) wird CBS-konvention als Nederlandse herkomst (Native) klassifiziert — V1-Modellgrenze, prominent dokumentiert wegen NL-historischer Tiefe (Indonesien-Generation 1949-1968 ist inzwischen 3./4. Gen und vollständig in Native).
A51: is | B51: Source of the data (verbal) | C51: {=IF(C52="","?",C52)&IF(C53="","","; downloaded "&C53)&IF(C54="","","; "&C54)}
B52: URLs, where the data was found | C52: https://www.cbs.nl/nl-nl/onze-diensten/methoden/begrippen/persoon-met-een-herkomst-buiten-nederland
B53: Date, when the data was downloaded | C53: 2026-05-26
B54: Manual remarks (not for AI!)
B55: Remarks of the AI (e.g. calculation) | C55: MH-Definition CBS seit Reform 16.02.2022 (ehemals 'autochtoon/allochtoon'). Operationalisierung: direkter Pull aus CBS 85384NED Herkomstland × Sex × Einzelalter. Native = Herkomstland Nederland; Migrant = Herkomstland Buiten Nederland. 1./2.-Gen-Split via Person-Geboorteland (1. Gen = im Ausland geboren; 2. Gen = in NL geboren mit MH-Herkomst). 3. Generation V2-Thema.
...

Sheet population
A1: population
C2: aa | D2: nf | E2: nm | F2: mf | G2: mm | H2: na | I2: ma | J2: af | K2: am
B3: {='overview'!C11&" / "&'overview'!C12} | C3: All | D3: Native Female | E3: Native Male | F3: Migrant Female | G3: Migrant Male | H3: Utility Native Male + Female | I3: Utility Migrant Male + Female | J3: Utility All Female | K3: Utility All Male | L3: Utility Other
B4: ⚠️ | C4: Do not add or delete lines until the next dark grey row below! The fields below are the fields used in other sheets and in the calculation. The address of these fields and their contents must remain always the same, so we can add calculations later!
B5: Population | C5: This is the base line of the caclution
A7: py | B7: Year of the count of the population | C7: 2025
A9: p00 | B9: 0 years | C9: {=H9+I9} | D9: {=D121} | E9: {=E121} | F9: {=F121} | G9: {=G121} | H9: {=E9+D9} | I9: {=G9+F9} | J9: {=D9+F9} | K9: {=E9+G9}
A10: p01 | B10: 1 years | C10: {=H10+I10} | D10: {=D122} | E10: {=E122} | F10: {=F122} | G10: {=G122} | H10: {=E10+D10} | I10: {=G10+F10} | J10: {=D10+F10} | K10: {=E10+G10}
A11: p02 | B11: 2 years | C11: {=H11+I11} | D11: {=D123} | E11: {=E123} | F11: {=F123} | G11: {=G123} | H11: {=E11+D11} | I11: {=G11+F11} | J11: {=D11+F11} | K11: {=E11+G11}
A12: p03 | B12: 3 years | C12: {=H12+I12} | D12: {=D124} | E12: {=E124} | F12: {=F124} | G12: {=G124} | H12: {=E12+D12} | I12: {=G12+F12} | J12: {=D12+F12} | K12: {=E12+G12}
A13: p04 | B13: 4 years | C13: {=H13+I13} | D13: {=D125} | E13: {=E125} | F13: {=F125} | G13: {=G125} | H13: {=E13+D13} | I13: {=G13+F13} | J13: {=D13+F13} | K13: {=E13+G13}
A14: p05 | B14: 5 years | C14: {=H14+I14} | D14: {=D126} | E14: {=E126} | F14: {=F126} | G14: {=G126} | H14: {=E14+D14} | I14: {=G14+F14} | J14: {=D14+F14} | K14: {=E14+G14}
A15: p06 | B15: 6 years | C15: {=H15+I15} | D15: {=D127} | E15: {=E127} | F15: {=F127} | G15: {=G127} | H15: {=E15+D15} | I15: {=G15+F15} | J15: {=D15+F15} | K15: {=E15+G15}
A16: p07 | B16: 7 years | C16: {=H16+I16} | D16: {=D128} | E16: {=E128} | F16: {=F128} | G16: {=G128} | H16: {=E16+D16} | I16: {=G16+F16} | J16: {=D16+F16} | K16: {=E16+G16}
A17: p08 | B17: 8 years | C17: {=H17+I17} | D17: {=D129} | E17: {=E129} | F17: {=F129} | G17: {=G129} | H17: {=E17+D17} | I17: {=G17+F17} | J17: {=D17+F17} | K17: {=E17+G17}
A18: p09 | B18: 9 years | C18: {=H18+I18} | D18: {=D130} | E18: {=E130} | F18: {=F130} | G18: {=G130} | H18: {=E18+D18} | I18: {=G18+F18} | J18: {=D18+F18} | K18: {=E18+G18}
A19: p10 | B19: 10 years | C19: {=H19+I19} | D19: {=D131} | E19: {=E131} | F19: {=F131} | G19: {=G131} | H19: {=E19+D19} | I19: {=G19+F19} | J19: {=D19+F19} | K19: {=E19+G19}
A20: p11 | B20: 11 years | C20: {=H20+I20} | D20: {=D132} | E20: {=E132} | F20: {=F132} | G20: {=G132} | H20: {=E20+D20} | I20: {=G20+F20} | J20: {=D20+F20} | K20: {=E20+G20}
... A108: p99 | B108: 99 years and older | C108: {=H108+I108} | D108: {=D220} | E108: {=E220} | F108: {=F220} | G108: {=G220} | H108: {=E108+D108} | I108: {=G108+F108} | J108: {=D108+F108} | K108: {=E108+G108}
A109: pt | B109: Total | C109: {=SUM(C9:C108)} | D109: {=SUM(D9:D108)} | E109: {=SUM(E9:E108)} | F109: {=SUM(F9:F108)} | G109: {=SUM(G9:G108)} | H109: {=SUM(H9:H108)} | I109: {=SUM(I9:I108)} | J109: {=D109+F109} | K109: {=E109+G109}
A111: ps | B111: Source of the data (verbal) | C111: {=IF(C112="","?",C112)&IF(C113="","","; downloaded "&C113)&IF(C114="","","; "&C114)}
B112: URLs, where the data was found | C112: https://opendata.cbs.nl/ODataApi/odata/85384NED/TypedDataSet
B113: Date, when the data was downloaded | C113: 2026-05-26
B114: Manual remarks (not for AI!)
B115: Remarks of the AI (e.g. calculation) | C115: Bevölkerung 01.01.2025 nach Sex × Einzelalter × Herkomstland aus CBS-Würfel 85384NED (Bevolking; geslacht, leeftijd, herkomstland en geboorteland (ouders), 1 jan). Native = Herkomstland 'Nederland' (CBS-Aggregat: Person in NL geboren + beide Eltern in NL geboren). Migrant = Herkomstland 'Buiten Nederland' (mind. ein Elternteil im Ausland geboren ODER selbst im Ausland geboren). Pop Total = 18,041,444 = CBS-Headline 17.999.027 ± Rundungen. Migrant-Anteil = 28.50%. **3.-Generation-Untererfassung** (User-Vorgabe prominent): CBS-Definition zählt nur 1.+2. Gen. Bei NL wegen Indonesien-Generation 1949-1968 (~300k 1.-Gen, inzwischen meist verstorben; deren Nachkommen ~600k+ als 2./3./4. Gen) sowie Suriname-Welle 1973-1975 substantielle 3.-Gen-Pop, die als Native gezählt wird → V1-Migrant-Anteil systematisch konservativ. Quantifizierung erfordert TeO-äquivalente Mikrodaten-Analyse, V2-Thema.
B116: Internal remarks
B118: ✏️ | C118: Enter your data below and make sure that you adjust the formulas above, if necessary. If calculations are necessary, use the fields below for it and use formulas in the area above, to fill in the fields above exactly as intended.
B119: Population | C119: Calculation of the population
B121: 0 years | D121: 57889 | E121: 60597 | F121: 23053 | G121: 24438
B122: 1 years | D122: 57581 | E122: 60110 | F122: 23141 | G122: 24624
B123: 2 years | D123: 58897 | E123: 61600 | F123: 24161 | G123: 25265
B124: 3 years | D124: 63755 | E124: 66787 | F124: 25744 | G124: 27117
B125: 4 years | D125: 59081 | E125: 61896 | F125: 25634 | G125: 27055
B126: 5 years | D126: 59049 | E126: 62042 | F126: 26707 | G126: 27903
B127: 6 years | D127: 59036 | E127: 61909 | F127: 26993 | G127: 28039
B128: 7 years | D128: 59738 | E128: 62950 | F128: 27153 | G128: 28567
B129: 8 years | D129: 60668 | E129: 64086 | F129: 27831 | G129: 29207
B130: 9 years | D130: 60536 | E130: 63579 | F130: 27915 | G130: 29526
B131: 10 years | D131: 62600 | E131: 65263 | F131: 28532 | G131: 30030
B132: 11 years | D132: 61306 | E132: 64567 | F132: 27641 | G132: 29581
...

Sheet births
A1: births
C2: aa | D2: nf | E2: nm | F2: mf | G2: mm | H2: na | I2: ma | J2: af | K2: am
B3: {='overview'!C11&" / "&'overview'!C12} | C3: All | D3: Native Female | E3: Native Male | F3: Migrant Female | G3: Migrant Male | H3: Utility Native Male + Female | I3: Utility Migrant Male + Female | J3: Utility All Female | K3: Utility All Male | L3: Utility Other
B4: ⚠️ | C4: Do not add or delete lines until the next dark grey row below! The fields below are the fields used in other sheets and in the calculation. The address of these fields and their contents must remain always the same, so we can add calculations later!
B5: Fertility | C5: The values in this section are used to calculate the number of births in the population goups
A7: f | B7: Official fertility rate | D7: 1.472 | F7: 1.355
B8: Population of age 0 (=births) | C8: {='population'!C9} | D8: {='population'!D9} | E8: {='population'!E9} | F8: {='population'!F9} | G8: {='population'!G9} | H8: {='population'!H9} | I8: {='population'!I9} | J8: {='population'!J9} | K8: {='population'!K9}
B9: Population of women of age 15-49 | D9: {=SUM('population'!D24:D58)} | F9: {=SUM('population'!F24:F58)}
B10: Factor: fertile women x fertility rate | C10: {=D10+F10} | D10: {=D9*D7} | F10: {=F9*F7}
A11: f00 | B11: Calculated births by fertility rate | C11: {=H11+I11} | D11: {=(D8+F8)*D10/C10} | E11: {=(E8+G8)*D10/C10} | F11: {=(D8+F8)*F10/C10} | G11: {=(E8+G8)*F10/C10} | H11: {=E11+D11} | I11: {=G11+F11} | J11: {=D11+F11} | K11: {=E11+G11}
A13: fs | B13: Source of the data (verbal) | C13: {=IF(C14="","?",C14)&IF(C15="","","; downloaded "&C15)&IF(C16="","","; "&C16)}
B14: URLs, where the data was found | C14: https://opendata.cbs.nl/ODataApi/odata/85730NED/TypedDataSet (Geboorte; vruchtbaarheid, herkomstland en geboorteland moeder)
B15: Date, when the data was downloaded | C15: 2026-05-26
B16: Manual remarks (not for AI!)
B17: Remarks of the AI (e.g. calculation) | C17: TFR 2024 direkt aus CBS-Würfel 85730NED (Topic 'GemiddeldKindertalPerVrouw'). Native = HerkomstlandMoeder Nederland: ZGZ = 1.472. Migrant = HerkomstlandMoeder Buiten Nederland: ZGZ = 1.355. Headline-Total = 1.426. **Wichtiger Befund**: Migrant-TFR (1.355) ist NIEDRIGER als Native-TFR (1.472) — entgegen Plan-Erwartung (1,40/1,70). Demografischer Trend in NL: Konvergenz nach unten der Migrant-Fertilität (Inburgering, Bildung, sinkende Familiengrößen v.a. bei 2. Gen, deren Anteil unter Migrant-Müttern wächst). CBS-Nenner = Jahresmittel-Frauenpop pro Mutter-Herkomstland-Klasse, konsistent zur CBS-Berechnung (kein eigener Nenner-Issue analog CH-V1). Methodische Approximation (CLAUDE.md): Migrant-TFR (Mutter-Herkomstland-basiert, inkl. 1./2. Gen Mütter) wird auf gesamte Migrant-Pop (1.+2. Gen) angewandt — konsistent. Im Endbericht als methodische Eigenheit ausweisen.
B18: Internal remarks
B20: Births | C20: The values in this section are used to calculate at which age of the mother the children are born
A22: b15 | B22: 15 years and younger age of the mother | C22: {=D22+E22+F22+G22} | D22: {=D$11*$H22/$H$57} | E22: {=E$11*$H22/$H$57} | F22: {=F$11*$I22/$I$57} | G22: {=G$11*$I22/$I$57} | H22: {=H74} | I22: {=I74} | J22: {=D22+F22} | K22: {=E22+G22}
A23: b16 | B23: 16 years age of the mother | C23: {=D23+E23+F23+G23} | D23: {=D$11*$H23/$H$57} | E23: {=E$11*$H23/$H$57} | F23: {=F$11*$I23/$I$57} | G23: {=G$11*$I23/$I$57} | H23: {=H75} | I23: {=I75} | J23: {=D23+F23} | K23: {=E23+G23}
A24: b17 | B24: 17 years age of the mother | C24: {=D24+E24+F24+G24} | D24: {=D$11*$H24/$H$57} | E24: {=E$11*$H24/$H$57} | F24: {=F$11*$I24/$I$57} | G24: {=G$11*$I24/$I$57} | H24: {=H76} | I24: {=I76} | J24: {=D24+F24} | K24: {=E24+G24}
A25: b18 | B25: 18 years age of the mother | C25: {=D25+E25+F25+G25} | D25: {=D$11*$H25/$H$57} | E25: {=E$11*$H25/$H$57} | F25: {=F$11*$I25/$I$57} | G25: {=G$11*$I25/$I$57} | H25: {=H77} | I25: {=I77} | J25: {=D25+F25} | K25: {=E25+G25}
A26: b19 | B26: 19 years age of the mother | C26: {=D26+E26+F26+G26} | D26: {=D$11*$H26/$H$57} | E26: {=E$11*$H26/$H$57} | F26: {=F$11*$I26/$I$57} | G26: {=G$11*$I26/$I$57} | H26: {=H78} | I26: {=I78} | J26: {=D26+F26} | K26: {=E26+G26}
A27: b20 | B27: 20 years age of the mother | C27: {=D27+E27+F27+G27} | D27: {=D$11*$H27/$H$57} | E27: {=E$11*$H27/$H$57} | F27: {=F$11*$I27/$I$57} | G27: {=G$11*$I27/$I$57} | H27: {=H79} | I27: {=I79} | J27: {=D27+F27} | K27: {=E27+G27}
A28: b21 | B28: 21 years age of the mother | C28: {=D28+E28+F28+G28} | D28: {=D$11*$H28/$H$57} | E28: {=E$11*$H28/$H$57} | F28: {=F$11*$I28/$I$57} | G28: {=G$11*$I28/$I$57} | H28: {=H80} | I28: {=I80} | J28: {=D28+F28} | K28: {=E28+G28}
A29: b22 | B29: 22 years age of the mother | C29: {=D29+E29+F29+G29} | D29: {=D$11*$H29/$H$57} | E29: {=E$11*$H29/$H$57} | F29: {=F$11*$I29/$I$57} | G29: {=G$11*$I29/$I$57} | H29: {=H81} | I29: {=I81} | J29: {=D29+F29} | K29: {=E29+G29}
A30: b23 | B30: 23 years age of the mother | C30: {=D30+E30+F30+G30} | D30: {=D$11*$H30/$H$57} | E30: {=E$11*$H30/$H$57} | F30: {=F$11*$I30/$I$57} | G30: {=G$11*$I30/$I$57} | H30: {=H82} | I30: {=I82} | J30: {=D30+F30} | K30: {=E30+G30}
A31: b24 | B31: 24 years age of the mother | C31: {=D31+E31+F31+G31} | D31: {=D$11*$H31/$H$57} | E31: {=E$11*$H31/$H$57} | F31: {=F$11*$I31/$I$57} | G31: {=G$11*$I31/$I$57} | H31: {=H83} | I31: {=I83} | J31: {=D31+F31} | K31: {=E31+G31}
A32: b25 | B32: 25 years age of the mother | C32: {=D32+E32+F32+G32} | D32: {=D$11*$H32/$H$57} | E32: {=E$11*$H32/$H$57} | F32: {=F$11*$I32/$I$57} | G32: {=G$11*$I32/$I$57} | H32: {=H84} | I32: {=I84} | J32: {=D32+F32} | K32: {=E32+G32}
A33: b26 | B33: 26 years age of the mother | C33: {=D33+E33+F33+G33} | D33: {=D$11*$H33/$H$57} | E33: {=E$11*$H33/$H$57} | F33: {=F$11*$I33/$I$57} | G33: {=G$11*$I33/$I$57} | H33: {=H85} | I33: {=I85} | J33: {=D33+F33} | K33: {=E33+G33}
... A56: b49 | B56: 49 years and older age of the mother | C56: {=D56+E56+F56+G56} | D56: {=D$11*$H56/$H$57} | E56: {=E$11*$H56/$H$57} | F56: {=F$11*$I56/$I$57} | G56: {=G$11*$I56/$I$57} | H56: {=H108} | I56: {=I108} | J56: {=D56+F56} | K56: {=E56+G56}
A57: bt | B57: Total | C57: {=SUM(C22:C56)} | D57: {=SUM(D22:D56)} | E57: {=SUM(E22:E56)} | F57: {=SUM(F22:F56)} | G57: {=SUM(G22:G56)} | H57: {=SUM(H22:H56)} | I57: {=SUM(I22:I56)} | J57: {=SUM(J22:J56)} | K57: {=SUM(K22:K56)}
A59: bs | B59: Source of the data (verbal) | C59: {=IF(C60="","?",C60)&IF(C61="","","; downloaded "&C61)&IF(C62="","","; "&C62)}
B60: URLs, where the data was found | C60: siehe C14
B61: Date, when the data was downloaded | C61: 2026-05-26
B62: Manual remarks (not for AI!)
B63: Remarks of the AI (e.g. calculation) | C63: ASFR-Shape (= absolute Geburten pro Mutter-Alter) in H74:H108 (Native, Mutter-Herkomstland Nederland) und I74:I108 (Migrant, Buiten-NL) aus CBS-Würfel 85497NED (Levend geboren kinderen; herkomstland moeder en leeftijd moeder). Filter: GeboortelandMoeder=Total (inkl. 1. und 2. Gen Mutter). Sum Native = 106,791, Sum Migrant = 59,266. Vorlagen-Formel Z. 22-56 nutzt H/I als ASFR-Profil; absolute Geburten via Top-Block H11/I11 (Sex-Ratio at Birth aus Pop Alter 0).
B64: Internal remarks
B66: ✏️ | C66: Enter your data below and make sure that you adjust the formulas above, if necessary. If calculations are necessary, use the fields below for it and use formulas in the area above, to fill in the fields above exactly as intended.
B67: Births | C67: Calculation of the births
B68: Use the fields of this row, if numbers for age, natives/migrants are known
...

Sheet deaths
A1: deaths
C2: aa | D2: nf | E2: nm | F2: mf | G2: mm | H2: na | I2: ma | J2: af | K2: am
B3: {='overview'!C11&" / "&'overview'!C12} | C3: All | D3: Native Female | E3: Native Male | F3: Migrant Female | G3: Migrant Male | H3: Utility Native Male + Female | I3: Utility Migrant Male + Female | J3: Utility All Female | K3: Utility All Male | L3: Utility Other
B4: ⚠️ | C4: Do not add or delete lines until the next dark grey row below! The fields below are the fields used in other sheets and in the calculation. The address of these fields and their contents must remain always the same, so we can add calculations later!
B5: Deaths | C5: This table is needed to calculate the Leslie matrix
A7: d00 | B7: 0 years age of the deceased | C7: {=H7+I7} | D7: {=D119} | E7: {=E119} | F7: {=F119} | G7: {=G119} | H7: {=E7+D7} | I7: {=G7+F7} | J7: {=D7+F7} | K7: {=E7+G7}
A8: d01 | B8: 1 years age of the deceased | C8: {=H8+I8} | D8: {=D120} | E8: {=E120} | F8: {=F120} | G8: {=G120} | H8: {=E8+D8} | I8: {=G8+F8} | J8: {=D8+F8} | K8: {=E8+G8}
A9: d02 | B9: 2 years age of the deceased | C9: {=H9+I9} | D9: {=D121} | E9: {=E121} | F9: {=F121} | G9: {=G121} | H9: {=E9+D9} | I9: {=G9+F9} | J9: {=D9+F9} | K9: {=E9+G9}
A10: d03 | B10: 3 years age of the deceased | C10: {=H10+I10} | D10: {=D122} | E10: {=E122} | F10: {=F122} | G10: {=G122} | H10: {=E10+D10} | I10: {=G10+F10} | J10: {=D10+F10} | K10: {=E10+G10}
A11: d04 | B11: 4 years age of the deceased | C11: {=H11+I11} | D11: {=D123} | E11: {=E123} | F11: {=F123} | G11: {=G123} | H11: {=E11+D11} | I11: {=G11+F11} | J11: {=D11+F11} | K11: {=E11+G11}
A12: d05 | B12: 5 years age of the deceased | C12: {=H12+I12} | D12: {=D124} | E12: {=E124} | F12: {=F124} | G12: {=G124} | H12: {=E12+D12} | I12: {=G12+F12} | J12: {=D12+F12} | K12: {=E12+G12}
A13: d06 | B13: 6 years age of the deceased | C13: {=H13+I13} | D13: {=D125} | E13: {=E125} | F13: {=F125} | G13: {=G125} | H13: {=E13+D13} | I13: {=G13+F13} | J13: {=D13+F13} | K13: {=E13+G13}
A14: d07 | B14: 7 years age of the deceased | C14: {=H14+I14} | D14: {=D126} | E14: {=E126} | F14: {=F126} | G14: {=G126} | H14: {=E14+D14} | I14: {=G14+F14} | J14: {=D14+F14} | K14: {=E14+G14}
A15: d08 | B15: 8 years age of the deceased | C15: {=H15+I15} | D15: {=D127} | E15: {=E127} | F15: {=F127} | G15: {=G127} | H15: {=E15+D15} | I15: {=G15+F15} | J15: {=D15+F15} | K15: {=E15+G15}
A16: d09 | B16: 9 years age of the deceased | C16: {=H16+I16} | D16: {=D128} | E16: {=E128} | F16: {=F128} | G16: {=G128} | H16: {=E16+D16} | I16: {=G16+F16} | J16: {=D16+F16} | K16: {=E16+G16}
A17: d10 | B17: 10 years age of the deceased | C17: {=H17+I17} | D17: {=D129} | E17: {=E129} | F17: {=F129} | G17: {=G129} | H17: {=E17+D17} | I17: {=G17+F17} | J17: {=D17+F17} | K17: {=E17+G17}
A18: d11 | B18: 11 years age of the deceased | C18: {=H18+I18} | D18: {=D130} | E18: {=E130} | F18: {=F130} | G18: {=G130} | H18: {=E18+D18} | I18: {=G18+F18} | J18: {=D18+F18} | K18: {=E18+G18}
... A106: d99 | B106: 99 years and older age of the deceased | C106: {=H106+I106} | D106: {=D218} | E106: {=E218} | F106: {=F218} | G106: {=G218} | H106: {=E106+D106} | I106: {=G106+F106} | J106: {=D106+F106} | K106: {=E106+G106}
A107: dt | B107: Total | C107: {=SUM(C7:C106)} | D107: {=SUM(D7:D106)} | E107: {=SUM(E7:E106)} | F107: {=SUM(F7:F106)} | G107: {=SUM(G7:G106)} | H107: {=SUM(H7:H106)} | I107: {=SUM(I7:I106)} | J107: {=D107+F107} | K107: {=E107+G107}
A109: ds | B109: Source of the data (verbal) | C109: {=IF(C110="","?",C110)&IF(C111="","","; downloaded "&C111)&IF(C112="","","; "&C112)}
B110: URLs, where the data was found | C110: https://opendata.cbs.nl/ODataApi/odata/85449NED/TypedDataSet (Overledenen; geslacht, leeftijd, herkomstland en geboorteland)
B111: Date, when the data was downloaded | C111: 2026-05-26
B112: Manual remarks (not for AI!)
B113: Remarks of the AI (e.g. calculation) | C113: Sterbefälle 2024 direkt aus CBS-Würfel 85449NED (Overledenen; Sex × Einzelalter × Herkomstland). Native = Herkomstland NL: 143,834; Migrant = Herkomstland Buiten-NL: 26,501; Total = 170,335. **CBS publiziert die MH-Aufschlüsselung direkt** — kein anteiliges Apportionment via Pop-Struktur nötig (anders als CH-V1, AT-V1, FR-V1, DE-V1 die alle das Apportionment-Workaround nutzten). Methodisch sauberer.
B114: Internal remarks
B116: ✏️ | C116: Enter your data below and make sure that you adjust the formulas above, if necessary. If calculations are necessary, use the fields below for it and use formulas in the area above, to fill in the fields above exactly as intended.
B117: Deaths | C117: Calculation of the deaths
B119: 0 years | D119: 167 | E119: 195 | F119: 65 | G119: 81
B120: 1 years | D120: 13 | E120: 24 | F120: 10 | G120: 6
B121: 2 years | D121: 8 | E121: 10 | F121: 9 | G121: 6
B122: 3 years | D122: 4 | E122: 11 | F122: 3 | G122: 5
B123: 4 years | D123: 2 | E123: 6 | F123: 1 | G123: 6
B124: 5 years | D124: 4 | E124: 2 | F124: 1 | G124: 3
B125: 6 years | D125: 2 | E125: 3 | F125: 1 | G125: 2
B126: 7 years | D126: 2 | E126: 4 | F126: 3 | G126: 5
B127: 8 years | D127: 3 | E127: 6 | F127: 4 | G127: 5
B128: 9 years | D128: 3 | E128: 7 | F128: 5 | G128: 3
B129: 10 years | D129: 4 | E129: 6 | F129: 2 | G129: 3
B130: 11 years | D130: 9 | E130: 9 | F130: 5 | G130: 3
... B218: 99 years and older | D218: 669 | E218: 234 | F218: 81 | G218: 28

Sheet migration
A1: migration
C2: aa | D2: nf | E2: nm | F2: mf | G2: mm | H2: na | I2: ma | J2: af | K2: am
B3: {='overview'!C11&" / "&'overview'!C12} | C3: All | D3: Native Female | E3: Native Male | F3: Migrant Female | G3: Migrant Male | H3: Utility Native Male + Female | I3: Utility Migrant Male + Female | J3: Utility All Female | K3: Utility All Male | L3: Utility Other
B4: ⚠️ | C4: Do not add or delete lines until the next dark grey row below! The fields below are the fields used in other sheets and in the calculation. The address of these fields and their contents must remain always the same, so we can add calculations later!
B5: Migration balance | C5: This is the total of immigrations (into the country) minus emigration (out of the country)
B7: Year of the last migration numbers | C7: 2024
A9: ma | B9: Avarage migration balance (10 years) | C9: {=H9+I9} | D9: {=D199-D286} | E9: {=E199-E286} | F9: {=F199-F286} | G9: {=G199-G286} | H9: {=E9+D9} | I9: {=G9+F9} | J9: {=D9+F9} | K9: {=E9+G9}
A11: m00 | B11: 0 years | C11: {=H11+I11} | D11: {=D$9*$L11} | E11: {=E$9*$L11} | F11: {=F$9*$L11} | G11: {=G$9*$L11} | H11: {=E11+D11} | I11: {=G11+F11} | J11: {=D11+F11} | K11: {=E11+G11}
A12: m01 | B12: 1 years | C12: {=H12+I12} | D12: {=D$9*$L12} | E12: {=E$9*$L12} | F12: {=F$9*$L12} | G12: {=G$9*$L12} | H12: {=E12+D12} | I12: {=G12+F12} | J12: {=D12+F12} | K12: {=E12+G12}
A13: m02 | B13: 2 years | C13: {=H13+I13} | D13: {=D$9*$L13} | E13: {=E$9*$L13} | F13: {=F$9*$L13} | G13: {=G$9*$L13} | H13: {=E13+D13} | I13: {=G13+F13} | J13: {=D13+F13} | K13: {=E13+G13}
A14: m03 | B14: 3 years | C14: {=H14+I14} | D14: {=D$9*$L14} | E14: {=E$9*$L14} | F14: {=F$9*$L14} | G14: {=G$9*$L14} | H14: {=E14+D14} | I14: {=G14+F14} | J14: {=D14+F14} | K14: {=E14+G14}
A15: m04 | B15: 4 years | C15: {=H15+I15} | D15: {=D$9*$L15} | E15: {=E$9*$L15} | F15: {=F$9*$L15} | G15: {=G$9*$L15} | H15: {=E15+D15} | I15: {=G15+F15} | J15: {=D15+F15} | K15: {=E15+G15}
A16: m05 | B16: 5 years | C16: {=H16+I16} | D16: {=D$9*$L16} | E16: {=E$9*$L16} | F16: {=F$9*$L16} | G16: {=G$9*$L16} | H16: {=E16+D16} | I16: {=G16+F16} | J16: {=D16+F16} | K16: {=E16+G16} | L16: 0.0001247127
A17: m06 | B17: 6 years | C17: {=H17+I17} | D17: {=D$9*$L17} | E17: {=E$9*$L17} | F17: {=F$9*$L17} | G17: {=G$9*$L17} | H17: {=E17+D17} | I17: {=G17+F17} | J17: {=D17+F17} | K17: {=E17+G17} | L17: 0.0002035291
A18: m07 | B18: 7 years | C18: {=H18+I18} | D18: {=D$9*$L18} | E18: {=E$9*$L18} | F18: {=F$9*$L18} | G18: {=G$9*$L18} | H18: {=E18+D18} | I18: {=G18+F18} | J18: {=D18+F18} | K18: {=E18+G18} | L18: 0.000325446
A19: m08 | B19: 8 years | C19: {=H19+I19} | D19: {=D$9*$L19} | E19: {=E$9*$L19} | F19: {=F$9*$L19} | G19: {=G$9*$L19} | H19: {=E19+D19} | I19: {=G19+F19} | J19: {=D19+F19} | K19: {=E19+G19} | L19: 0.0005098804
A20: m09 | B20: 9 years | C20: {=H20+I20} | D20: {=D$9*$L20} | E20: {=E$9*$L20} | F20: {=F$9*$L20} | G20: {=G$9*$L20} | H20: {=E20+D20} | I20: {=G20+F20} | J20: {=D20+F20} | K20: {=E20+G20} | L20: 0.0007826985
A21: m10 | B21: 10 years | C21: {=H21+I21} | D21: {=D$9*$L21} | E21: {=E$9*$L21} | F21: {=F$9*$L21} | G21: {=G$9*$L21} | H21: {=E21+D21} | I21: {=G21+F21} | J21: {=D21+F21} | K21: {=E21+G21} | L21: 0.0011772198
A22: m11 | B22: 11 years | C22: {=H22+I22} | D22: {=D$9*$L22} | E22: {=E$9*$L22} | F22: {=F$9*$L22} | G22: {=G$9*$L22} | H22: {=E22+D22} | I22: {=G22+F22} | J22: {=D22+F22} | K22: {=E22+G22} | L22: 0.0017348322
A23: m12 | B23: 12 years | C23: {=H23+I23} | D23: {=D$9*$L23} | E23: {=E$9*$L23} | F23: {=F$9*$L23} | G23: {=G$9*$L23} | H23: {=E23+D23} | I23: {=G23+F23} | J23: {=D23+F23} | K23: {=E23+G23} | L23: 0.002504922
A24: m13 | B24: 13 years | C24: {=H24+I24} | D24: {=D$9*$L24} | E24: {=E$9*$L24} | F24: {=F$9*$L24} | G24: {=G$9*$L24} | H24: {=E24+D24} | I24: {=G24+F24} | J24: {=D24+F24} | K24: {=E24+G24} | L24: 0.0035437886
A25: m14 | B25: 14 years | C25: {=H25+I25} | D25: {=D$9*$L25} | E25: {=E$9*$L25} | F25: {=F$9*$L25} | G25: {=G$9*$L25} | H25: {=E25+D25} | I25: {=G25+F25} | J25: {=D25+F25} | K25: {=E25+G25} | L25: 0.004912225
A26: m15 | B26: 15 years | C26: {=H26+I26} | D26: {=D$9*$L26} | E26: {=E$9*$L26} | F26: {=F$9*$L26} | G26: {=G$9*$L26} | H26: {=E26+D26} | I26: {=G26+F26} | J26: {=D26+F26} | K26: {=E26+G26} | L26: 0.0066715315
A27: m16 | B27: 16 years | C27: {=H27+I27} | D27: {=D$9*$L27} | E27: {=E$9*$L27} | F27: {=F$9*$L27} | G27: {=G$9*$L27} | H27: {=E27+D27} | I27: {=G27+F27} | J27: {=D27+F27} | K27: {=E27+G27} | L27: 0.0088778883
... A65: m54 | B65: 54 years | C65: {=H65+I65} | D65: {=D$9*$L65} | E65: {=E$9*$L65} | F65: {=F$9*$L65} | G65: {=G$9*$L65} | H65: {=E65+D65} | I65: {=G65+F65} | J65: {=D65+F65} | K65: {=E65+G65} | L65: 0.0001247127
A66: m55 | B66: 55 years | C66: {=H66+I66} | D66: {=D$9*$L66} | E66: {=E$9*$L66} | F66: {=F$9*$L66} | G66: {=G$9*$L66} | H66: {=E66+D66} | I66: {=G66+F66} | J66: {=D66+F66} | K66: {=E66+G66}
A67: m56 | B67: 56 years | C67: {=H67+I67} | D67: {=D$9*$L67} | E67: {=E$9*$L67} | F67: {=F$9*$L67} | G67: {=G$9*$L67} | H67: {=E67+D67} | I67: {=G67+F67} | J67: {=D67+F67} | K67: {=E67+G67}
A68: m57 | B68: 57 years | C68: {=H68+I68} | D68: {=D$9*$L68} | E68: {=E$9*$L68} | F68: {=F$9*$L68} | G68: {=G$9*$L68} | H68: {=E68+D68} | I68: {=G68+F68} | J68: {=D68+F68} | K68: {=E68+G68}
A69: m58 | B69: 58 years | C69: {=H69+I69} | D69: {=D$9*$L69} | E69: {=E$9*$L69} | F69: {=F$9*$L69} | G69: {=G$9*$L69} | H69: {=E69+D69} | I69: {=G69+F69} | J69: {=D69+F69} | K69: {=E69+G69}
A70: m59 | B70: 59 years | C70: {=H70+I70} | D70: {=D$9*$L70} | E70: {=E$9*$L70} | F70: {=F$9*$L70} | G70: {=G$9*$L70} | H70: {=E70+D70} | I70: {=G70+F70} | J70: {=D70+F70} | K70: {=E70+G70}
A71: m60 | B71: 60 years | C71: {=H71+I71} | D71: {=D$9*$L71} | E71: {=E$9*$L71} | F71: {=F$9*$L71} | G71: {=G$9*$L71} | H71: {=E71+D71} | I71: {=G71+F71} | J71: {=D71+F71} | K71: {=E71+G71}
A72: m61 | B72: 61 years | C72: {=H72+I72} | D72: {=D$9*$L72} | E72: {=E$9*$L72} | F72: {=F$9*$L72} | G72: {=G$9*$L72} | H72: {=E72+D72} | I72: {=G72+F72} | J72: {=D72+F72} | K72: {=E72+G72}
A73: m62 | B73: 62 years | C73: {=H73+I73} | D73: {=D$9*$L73} | E73: {=E$9*$L73} | F73: {=F$9*$L73} | G73: {=G$9*$L73} | H73: {=E73+D73} | I73: {=G73+F73} | J73: {=D73+F73} | K73: {=E73+G73}
A74: m63 | B74: 63 years | C74: {=H74+I74} | D74: {=D$9*$L74} | E74: {=E$9*$L74} | F74: {=F$9*$L74} | G74: {=G$9*$L74} | H74: {=E74+D74} | I74: {=G74+F74} | J74: {=D74+F74} | K74: {=E74+G74}
A75: m64 | B75: 64 years | C75: {=H75+I75} | D75: {=D$9*$L75} | E75: {=E$9*$L75} | F75: {=F$9*$L75} | G75: {=G$9*$L75} | H75: {=E75+D75} | I75: {=G75+F75} | J75: {=D75+F75} | K75: {=E75+G75}
A76: m65 | B76: 65 years | C76: {=H76+I76} | D76: {=D$9*$L76} | E76: {=E$9*$L76} | F76: {=F$9*$L76} | G76: {=G$9*$L76} | H76: {=E76+D76} | I76: {=G76+F76} | J76: {=D76+F76} | K76: {=E76+G76}
A77: m66 | B77: 66 years | C77: {=H77+I77} | D77: {=D$9*$L77} | E77: {=E$9*$L77} | F77: {=F$9*$L77} | G77: {=G$9*$L77} | H77: {=E77+D77} | I77: {=G77+F77} | J77: {=D77+F77} | K77: {=E77+G77}
... A110: m99 | B110: 99 years and older | C110: {=H110+I110} | D110: {=D$9*$L110} | E110: {=E$9*$L110} | F110: {=F$9*$L110} | G110: {=G$9*$L110} | H110: {=E110+D110} | I110: {=G110+F110} | J110: {=D110+F110} | K110: {=E110+G110}
A111: mt | B111: Total | C111: {=SUM(C11:C110)} | D111: {=SUM(D11:D110)} | E111: {=SUM(E11:E110)} | F111: {=SUM(F11:F110)} | G111: {=SUM(G11:G110)} | H111: {=SUM(H11:H110)} | I111: {=SUM(I11:I110)} | J111: {=D111+F111} | K111: {=E111+G111}
A113: ms | B113: Source of the data (verbal) | C113: {=IF(C114="","?",C114)&IF(C115="","","; downloaded "&C115)&IF(C116="","","; "&C116)}
...

Sheet origin
A1: origin
C2: aa | D2: nf | E2: nm | F2: mf | G2: mm | H2: na | I2: ma | J2: af | K2: am
B3: {='overview'!C11&" / "&'overview'!C12} | C3: All | D3: Native Female | E3: Native Male | F3: Migrant Female | G3: Migrant Male | H3: Utility Native Male + Female | I3: Utility Migrant Male + Female | J3: Utility All Female | K3: Utility All Male | L3: Utility Other
B4: ✏️ | C4: Enter your data below and make sure that you adjust the formulas above, if necessary. If calculations are necessary, use the fields below for it and use formulas in the area above, to fill in the fields above exactly as intended.
B5: Origin of Migrants | C5: This table contains the countries the current migrants come from.
B7: Year of the numbers | C7: 2025
B9: Europe
A10: c1ad | B10: Andorra | C10: AD | F10: 19 | G10: 24 | I10: {=G10+F10}
A11: c1al | B11: Albania | C11: AL | F11: 2072 | G11: 2083 | I11: {=G11+F11}
A12: c1at | B12: Austria | C12: AT | F12: 4383 | G12: 3195 | I12: {=G12+F12}
A13: c1ax | B13: Åland Islands | C13: AX | I13: {=G13+F13}
A14: c1ba | B14: Bosnia and Herzegovina | C14: BA | I14: {=G14+F14}
A15: c1be | B15: Belgium | C15: BE | F15: 35806 | G15: 31496 | I15: {=G15+F15}
A16: c1bg | B16: Bulgaria | C16: BG | F16: 26168 | G16: 27449 | I16: {=G16+F16}
A17: c1by | B17: Belarus | C17: BY | I17: {=G17+F17}
A18: c1ch | B18: Switzerland | C18: CH | F18: 4992 | G18: 4151 | I18: {=G18+F18}
A19: c1cz | B19: Czechia[i] | C19: CZ | F19: 4906 | G19: 3189 | I19: {=G19+F19}
A20: c1de | B20: Germany | C20: DE | F20: 71194 | G20: 51756 | I20: {=G20+F20}
A21: c1dk | B21: Denmark | C21: DK | F21: 2440 | G21: 1852 | I21: {=G21+F21}
A22: c1ee | B22: Estonia | C22: EE | F22: 1546 | G22: 838 | I22: {=G22+F22}
A23: c1es | B23: Spain | C23: ES | F23: 22360 | G23: 22147 | I23: {=G23+F23}
A24: c1fi | B24: Finland | C24: FI | F24: 2969 | G24: 1357 | I24: {=G24+F24}
A25: c1fo | B25: Faroe Islands (the) | C25: FO | I25: {=G25+F25}
A26: c1fr | B26: France | C26: FR | F26: 19338 | G26: 16843 | I26: {=G26+F26}
A27: c1gb | B27: United Kingdom of Great Britain and Northern Ireland (the) | C27: GB | F27: 27553 | G27: 33877 | I27: {=G27+F27}
A28: c1gg | B28: Guernsey | C28: GG | I28: {=G28+F28}
A29: c1gi | B29: Gibraltar | C29: GI | I29: {=G29+F29}
A30: c1gr | B30: Greece | C30: GR | F30: 13625 | G30: 17648 | I30: {=G30+F30}
A31: c1hr | B31: Croatia | C31: HR | F31: 5130 | G31: 4754 | I31: {=G31+F31}
A32: c1hu | B32: Hungary | C32: HU | F32: 12307 | G32: 11193 | I32: {=G32+F32}
A33: c1ie | B33: Ireland | C33: IE | F33: 4501 | G33: 5135 | I33: {=G33+F33}
A34: c1im | B34: Isle of Man | C34: IM | I34: {=G34+F34}
A35: c1is | B35: Iceland | C35: IS | F35: 345 | G35: 269 | I35: {=G35+F35}
A36: c1it | B36: Italy | C36: IT | F36: 21197 | G36: 27683 | I36: {=G36+F36}
A37: c1je | B37: Jersey | C37: JE | I37: {=G37+F37}
A38: c1li | B38: Liechtenstein | C38: LI | F38: 3 | G38: 0 | I38: {=G38+F38}
A39: c1lt | B39: Lithuania | C39: LT | F39: 6509 | G39: 5197 | I39: {=G39+F39}
A40: c1lu | B40: Luxembourg | C40: LU | F40: 1210 | G40: 1094 | I40: {=G40+F40}
A41: c1lv | B41: Latvia | C41: LV | F41: 4841 | G41: 4463 | I41: {=G41+F41}
A42: c1mc | B42: Monaco | C42: MC | F42: 68 | G42: 61 | I42: {=G42+F42}
...

Sheet patria
A1: patria
C2: aa | D2: nf | E2: nm | F2: mf | G2: mm | H2: na | I2: ma | J2: af | K2: am
B3: {='overview'!C11&" / "&'overview'!C12} | C3: All | D3: Native Female | E3: Native Male | F3: Migrant Female | G3: Migrant Male | H3: Utility Native Male + Female | I3: Utility Migrant Male + Female | J3: Utility All Female | K3: Utility All Male | L3: Utility Other
B4: ✏️ | C4: Enter your data below and make sure that you adjust the formulas above, if necessary. If calculations are necessary, use the fields below for it and use formulas in the area above, to fill in the fields above exactly as intended.
B5: Naturalisation | C5: Fill in the numbers of people being naturalized in the specified year. This is not relevant for the calculation of version 1 but it is important for future versions.
B7: Year of the last migration numbers | C7: 2024
B9: {=$B10-1} | C9: {=I9} | I9: 3000
B10: {=$B11-1} | C10: {=I10} | I10: 3000
B11: {=$B12-1} | C11: {=I11} | I11: 3000
B12: {=$B13-1} | C12: {=I12} | I12: 4000
B13: {=$B14-1} | C13: {=I13} | I13: 3000
B14: {=$B15-1} | C14: {=I14} | I14: 7000
B15: {=$B16-1} | C15: {=I15} | I15: 4000
B16: {=$B17-1} | C16: {=I16} | I16: 3000
B17: {=$B18-1} | C17: {=I17} | I17: 4000
B18: {=$B19-1} | C18: {=I18} | I18: 3000
B19: {=$B20-1} | C19: {=I19} | I19: 2000
B20: {=$B21-1} | C20: {=I20} | I20: 3000
... B44: {=$B45-1} | C44: {=I44} | I44: 9000
B45: {=$B46-1} | C45: {=I45} | F45: 15485 | G45: 19186 | I45: {=G45+F45}
B46: {=$B47-1} | C46: {=I46} | F46: 8112 | G46: 10646 | I46: {=G46+F46}
B47: {=$B48-1} | C47: {=I47} | F47: 8824 | G47: 10434 | I47: {=G47+F47}
B48: {=$B49-1} | C48: {=I48} | F48: 3976 | G48: 5138 | I48: {=G48+F48}
B49: {=$B50-1} | C49: {=I49} | F49: 12329 | G49: 16401 | I49: {=G49+F49}
B50: {=$B51-1} | C50: {=I50} | F50: 5697 | G50: 7097 | I50: {=G50+F50}
B51: {=$B52-1} | C51: {=I51} | F51: 13406 | G51: 15706 | I51: {=G51+F51}
B52: {=$B53-1} | C52: {=I52} | F52: 16884 | G52: 19353 | I52: {=G52+F52}
B53: {=$B54-1} | C53: {=I53} | F53: 20593 | G53: 22476 | I53: {=G53+F53}
B54: {=$B55-1} | C54: {=I54} | F54: 23372 | G54: 26076 | I54: {=G54+F54}
B55: {=$B56-1} | C55: {=I55} | F55: 33713 | G55: 37731 | I55: {=G55+F55}
B56: {=$B57-1} | C56: {=I56} | F56: 38951 | G56: 43736 | I56: {=G56+F56}
... B83: {=$B84-1} | C83: {=I83} | F83: 30382 | G83: 26519 | I83: {=G83+F83}
B84: {=$C$7} | C84: {=I84} | F84: 30714 | G84: 28285 | I84: {=G84+F84}
C85: {=SUM(C9:C84)} | F85: {=SUM(F9:F84)} | G85: {=SUM(G9:G84)} | I85: {=SUM(I9:I84)}
B87: Source of the data (verbal) | C87: {=IF(C88="","?",C88)&IF(C89="","","; downloaded "&C89)&IF(C90="","","; "&C90)}
B88: URLs, where the data was found | C88: https://opendata.cbs.nl/ODataApi/odata/37199NED/TypedDataSet (1985-2024 mit Sex-Split + Optie/Verlening-Aufschlüsselung); https://opendata.cbs.nl/ODataApi/odata/85524NED/TypedDataSet (1946-1984 Total)
B89: Date, when the data was downloaded | C89: 2026-05-26
B90: Manual remarks (not for AI!)
B91: Remarks of the AI (e.g. calculation) | C91: Naturalisationen 1949-2024 aus zwei CBS-Tabellen (CLAUDE.md-V1-Pflicht historische Reihen, nicht V1.x). 1985-2024: CBS 37199NED 'Nationaliteitswijziging' mit Geschlechts-Split und Aufschlüsselung TotaalVerkrijgingNederlanderschap_1 (= Naturalisatie/Verlening + Optie + Medenaturalisation + Adoption + Erkenning). Ersetzt Eurostat migr_acq als Primärquelle (Eurostat-Werte = direkte CBS-Übermittlung dieser Tabelle; nationale Quelle gemäß CLAUDE.md Vorrang). Optie-vs-Naturalisatie-Trennung direkt verfügbar: 2024 Total 58.999 = Verlening 52.056 + Optie 6.567 + Medenaturalisation + Adoption + Erkenning. Beide rein-resident → keine Filterung nötig. 1949-1984: CBS 85524NED 'Bevolking, huishoudens en bevolkingsontwikkeling; vanaf 1899' Topic 'Naturalisatie_206' (in Tausend, klassische Naturalisatie ohne Optie). Lücken-Konvention I-Spalte (Total only, kein Sex-Split publiziert für diesen Zeitraum, AT-V3-Präzedenz). Originalformel I=F+G mit Total überschrieben. **Methodenbruch 1976/1977 (resident-only-Filter)**: 1946-1976 schließt 85524NED-Naturalisatie-Reihe Auslands-Einbürgerungen mit ein (Personen außerhalb NL die durch Naturalisationsverfahren NL-Bürger wurden — analog AT-§58c-Effekt). Ab 1977 resident-only-Filter durch RWN-Verschärfung. Pre-1977-Werte daher leicht überzeichnet (Größenordnung ~10-20% zusätzlich, schwankend). 1985-2024-Reihe (37199NED) ist definitionsgemäß resident-only. **Methodenbrüche RWN**: 1985 (neues StAng-Gesetz, ablöste Wet op het Nederlanderschap 1892), 2003-04-01 (strengere Inburgering-Anforderungen, Sprung-erwartet), 2010, 2017 (Inburgering-Plicht erweitert). Historische Reihen (1949-1994) liegen außerhalb des 10-J-Ø-Kipppunkt-Fensters 2015-2024 — sie beeinflussen die overview-Berechnung nicht. CLAUDE.md-V1-Pflicht zur publizistischen Tiefe und Cross-Country-Konsistenz.
B92: Internal remarks
...

Sheet export
A1: export
C2: aa | D2: nf | E2: nm | F2: mf | G2: mm | H2: na | I2: ma | J2: af | K2: am
B3: {='overview'!C11&" / "&'overview'!C12} | C3: All | D3: Native Female | E3: Native Male | F3: Migrant Female | G3: Migrant Male | H3: Utility Native Male + Female | I3: Utility Migrant Male + Female | J3: Utility All Female | K3: Utility All Male | L3: Utility Other
B4: ⚠️ | C4: Do not change this sheet!
B5: Overview
A6: {='overview'!A11} | C6: {='overview'!C11}
A7: {='overview'!A12} | C7: {='overview'!C12}
A8: {='overview'!$A49} | C8: {='overview'!C49}
A9: {='overview'!$A51} | C9: {='overview'!C51}
A10: {='overview'!$A60} | C10: {='overview'!C60} | D10: {='overview'!D60} | E10: {='overview'!E60} | F10: {='overview'!F60} | G10: {='overview'!G60} | H10: {='overview'!H60} | I10: {='overview'!I60} | J10: {='overview'!J60} | K10: {='overview'!K60}
A11: {='overview'!$A62} | C11: {='overview'!C62}
B13: Population
A14: {='population'!$A7} | C14: {='population'!C7}
A15: {='population'!$A9} | C15: {='population'!C9} | D15: {='population'!D9} | E15: {='population'!E9} | F15: {='population'!F9} | G15: {='population'!G9} | H15: {='population'!H9} | I15: {='population'!I9} | J15: {='population'!J9} | K15: {='population'!K9}
A16: {='population'!$A10} | C16: {='population'!C10} | D16: {='population'!D10} | E16: {='population'!E10} | F16: {='population'!F10} | G16: {='population'!G10} | H16: {='population'!H10} | I16: {='population'!I10} | J16: {='population'!J10} | K16: {='population'!K10}
A17: {='population'!$A11} | C17: {='population'!C11} | D17: {='population'!D11} | E17: {='population'!E11} | F17: {='population'!F11} | G17: {='population'!G11} | H17: {='population'!H11} | I17: {='population'!I11} | J17: {='population'!J11} | K17: {='population'!K11}
A18: {='population'!$A12} | C18: {='population'!C12} | D18: {='population'!D12} | E18: {='population'!E12} | F18: {='population'!F12} | G18: {='population'!G12} | H18: {='population'!H12} | I18: {='population'!I12} | J18: {='population'!J12} | K18: {='population'!K12}
A19: {='population'!$A13} | C19: {='population'!C13} | D19: {='population'!D13} | E19: {='population'!E13} | F19: {='population'!F13} | G19: {='population'!G13} | H19: {='population'!H13} | I19: {='population'!I13} | J19: {='population'!J13} | K19: {='population'!K13}
A20: {='population'!$A14} | C20: {='population'!C14} | D20: {='population'!D14} | E20: {='population'!E14} | F20: {='population'!F14} | G20: {='population'!G14} | H20: {='population'!H14} | I20: {='population'!I14} | J20: {='population'!J14} | K20: {='population'!K14}
A21: {='population'!$A15} | C21: {='population'!C15} | D21: {='population'!D15} | E21: {='population'!E15} | F21: {='population'!F15} | G21: {='population'!G15} | H21: {='population'!H15} | I21: {='population'!I15} | J21: {='population'!J15} | K21: {='population'!K15}
A22: {='population'!$A16} | C22: {='population'!C16} | D22: {='population'!D16} | E22: {='population'!E16} | F22: {='population'!F16} | G22: {='population'!G16} | H22: {='population'!H16} | I22: {='population'!I16} | J22: {='population'!J16} | K22: {='population'!K16}
A23: {='population'!$A17} | C23: {='population'!C17} | D23: {='population'!D17} | E23: {='population'!E17} | F23: {='population'!F17} | G23: {='population'!G17} | H23: {='population'!H17} | I23: {='population'!I17} | J23: {='population'!J17} | K23: {='population'!K17}
A24: {='population'!$A18} | C24: {='population'!C18} | D24: {='population'!D18} | E24: {='population'!E18} | F24: {='population'!F18} | G24: {='population'!G18} | H24: {='population'!H18} | I24: {='population'!I18} | J24: {='population'!J18} | K24: {='population'!K18}
A25: {='population'!$A19} | C25: {='population'!C19} | D25: {='population'!D19} | E25: {='population'!E19} | F25: {='population'!F19} | G25: {='population'!G19} | H25: {='population'!H19} | I25: {='population'!I19} | J25: {='population'!J19} | K25: {='population'!K19}
A26: {='population'!$A20} | C26: {='population'!C20} | D26: {='population'!D20} | E26: {='population'!E20} | F26: {='population'!F20} | G26: {='population'!G20} | H26: {='population'!H20} | I26: {='population'!I20} | J26: {='population'!J20} | K26: {='population'!K20}
... A115: {='population'!$A109} | C115: {='population'!C109} | D115: {='population'!D109} | E115: {='population'!E109} | F115: {='population'!F109} | G115: {='population'!G109} | H115: {='population'!H109} | I115: {='population'!I109} | J115: {='population'!J109} | K115: {='population'!K109}
A116: {='population'!$A111} | C116: {='population'!C111}
B118: Births
A119: {='births'!$A7} | H119: {='births'!D7} | I119: {='births'!F7}
A120: {='births'!$A11} | C120: {='births'!C11} | D120: {='births'!D11} | E120: {='births'!E11} | F120: {='births'!F11} | G120: {='births'!G11} | H120: {='births'!H11} | I120: {='births'!I11} | J120: {='births'!J11} | K120: {='births'!K11}
A121: {='births'!$A13} | C121: {='births'!C13}
A122: {='births'!$A22} | C122: {='births'!C22} | D122: {='births'!D22} | E122: {='births'!E22} | F122: {='births'!F22} | G122: {='births'!G22} | H122: {='births'!H22} | I122: {='births'!I22} | J122: {='births'!J22} | K122: {='births'!K22}
A123: {='births'!$A23} | C123: {='births'!C23} | D123: {='births'!D23} | E123: {='births'!E23} | F123: {='births'!F23} | G123: {='births'!G23} | H123: {='births'!H23} | I123: {='births'!I23} | J123: {='births'!J23} | K123: {='births'!K23}
A124: {='births'!$A24} | C124: {='births'!C24} | D124: {='births'!D24} | E124: {='births'!E24} | F124: {='births'!F24} | G124: {='births'!G24} | H124: {='births'!H24} | I124: {='births'!I24} | J124: {='births'!J24} | K124: {='births'!K24}
A125: {='births'!$A25} | C125: {='births'!C25} | D125: {='births'!D25} | E125: {='births'!E25} | F125: {='births'!F25} | G125: {='births'!G25} | H125: {='births'!H25} | I125: {='births'!I25} | J125: {='births'!J25} | K125: {='births'!K25}
A126: {='births'!$A26} | C126: {='births'!C26} | D126: {='births'!D26} | E126: {='births'!E26} | F126: {='births'!F26} | G126: {='births'!G26} | H126: {='births'!H26} | I126: {='births'!I26} | J126: {='births'!J26} | K126: {='births'!K26}
A127: {='births'!$A27} | C127: {='births'!C27} | D127: {='births'!D27} | E127: {='births'!E27} | F127: {='births'!F27} | G127: {='births'!G27} | H127: {='births'!H27} | I127: {='births'!I27} | J127: {='births'!J27} | K127: {='births'!K27}
A128: {='births'!$A28} | C128: {='births'!C28} | D128: {='births'!D28} | E128: {='births'!E28} | F128: {='births'!F28} | G128: {='births'!G28} | H128: {='births'!H28} | I128: {='births'!I28} | J128: {='births'!J28} | K128: {='births'!K28}
A129: {='births'!$A29} | C129: {='births'!C29} | D129: {='births'!D29} | E129: {='births'!E29} | F129: {='births'!F29} | G129: {='births'!G29} | H129: {='births'!H29} | I129: {='births'!I29} | J129: {='births'!J29} | K129: {='births'!K29}
A130: {='births'!$A30} | C130: {='births'!C30} | D130: {='births'!D30} | E130: {='births'!E30} | F130: {='births'!F30} | G130: {='births'!G30} | H130: {='births'!H30} | I130: {='births'!I30} | J130: {='births'!J30} | K130: {='births'!K30}
...
